Workbook

Sheet Annexe 6 (3)
A1: MONSTER GARAGE
D11: Relevé des Factures | F11: Date: | G11: 46141
D13: A
C15: La Société Nationale des Transports et de la Logistique (SNTL)
B18: Partenaire
B19: N° Agrément SNTL | C19: 3108
B20: Raison Sociale | C20: WIDINE MOTORS SERVICES
B21: Adresse | C21: N°534 BIS 2 Q.I Sidi Ghanem
B22: Ville | C22: Marrakech
B23: RC | C23: 150241
B24: Patente | C24: 64006750
B25: IF | C25: 65976431
B26: ICE | C26: 003524622000063
B27: N° RIB | C27: 007450000612500000095129
B31: N° Facture | C31: Date facture | D31: N° Bon SNTL | E31: Montant TTC | F31: Commission SNTL | G31: Montant à régler
B32: =+'Annexe 31'!E11 -> 20260103 | C32: =+'Annexe 7'!G11 -> 46141 | D32: 260429000039 | E32: =+'Annexe 31'!G40 -> 8379.996 | F32: =+E32*0.1 -> 837.9996 | G32: =+E32-F32 -> 7541.9964
B33: =+'Annexe 32'!E11 -> 20260105 | C33: =+'Annexe 8'!G11 -> 46141 | D33: 260429000047 | E33: =+'Annexe 32'!G40 -> 8379.996 | F33: =+E33*0.1 -> 837.9996 | G33: =+E33-F33 -> 7541.9964
B34: =+'Annexe 33'!E11 -> 2026099 | C34: 46141 | D34: 260429000036 | E34: =+'Annexe 33'!G40 -> 8379.996 | F34: =+E34*0.1 -> 837.9996 | G34: =+E34-F34 -> 7541.9964
B35: =+'Annexe 34'!E11 -> 20260100 | C35: 47237 | D35: 260429000060 | E35: =+'Annexe 34'!G46 -> 9962.004 | F35: =+E35*0.1 -> 996.2004 | G35: =+E35-F35 -> 8965.8036
B36: =+'Annexe 35'!E11 -> 20260107 | C36: 46141 | D36: 260429000055 | E36: =+'Annexe 35'!G41 -> 3747 | F36: =+E36*0.1 -> 374.7 | G36: =+E36-F36 -> 3372.3
B37: =+'Annexe 36'!E11 -> 20260108 | C37: 46141 | D37: 260429000037 | E37: =+'Annexe 36'!G41 -> 19290 | F37: =+E37*0.1 -> 1929 | G37: =+E37-F37 -> 17361
B40: Total | E40: 58139 | F40: =SUM(F32:F39) -> 5813.8992 | G40: 52325.1
E43: Cachet et Signature

Sheet Annexe 6 (2)
A1: MONSTER GARAGE
D11: Relevé des Factures | F11: Date: | G11: 46141
D13: A
C15: La Société Nationale des Transports et de la Logistique (SNTL)
B18: Partenaire
B19: N° Agrément SNTL | C19: 3108
B20: Raison Sociale | C20: WIDINE MOTORS SERVICES
B21: Adresse | C21: N°534 BIS 2 Q.I Sidi Ghanem
B22: Ville | C22: Marrakech
B23: RC | C23: 150241
B24: Patente | C24: 64006750
B25: IF | C25: 65976431
B26: ICE | C26: 003524622000063
B27: N° RIB | C27: 007450000612500000095129
B31: N° Facture | C31: Date facture | D31: N° Bon SNTL | E31: Montant TTC | F31: Commission SNTL | G31: Montant à régler
B32: =+'Annexe 18'!E11 -> 2026075 | C32: =+'Annexe 7'!G11 -> 46141 | D32: 2605429000029 | E32: =+'Annexe 18'!G44 -> 2280 | F32: =+E32*0.1 -> 228 | G32: =+E32-F32 -> 2052
B33: =+'Annexe 19'!E11 -> 2026076 | C33: =+'Annexe 8'!G11 -> 46141 | D33: 2605429000067 | E33: =+'Annexe 19'!G43 -> 1920 | F33: =+E33*0.1 -> 192 | G33: =+E33-F33 -> 1728
B34: =+'Annexe 20'!E11 -> 2026074 | C34: 46141 | D34: 2605429000041 | E34: =+'Annexe 20'!G42 -> 19787.004 | F34: =+E34*0.1 -> 1978.7004 | G34: =+E34-F34 -> 17808.304
B35: =+'Annexe 21'!E11 -> 2026082 | C35: 46141 | D35: 2605429000034 | E35: =+'Annexe 21'!G52 -> 12215.484 | F35: =+E35*0.1 -> 1221.5484 | G35: =+E35-F35 -> 10993.936
B36: =+'Annexe 22 '!E11 -> 2026079 | C36: 46141 | D36: 2605429000033 | E36: =+'Annexe 22 '!G43 -> 16181.58 | F36: =+E36*0.1 -> 1618.158 | G36: =+E36-F36 -> 14563.422
B37: =+'Annexe 23'!E11 -> 2026080 | C37: 46141 | D37: 2605429000030 | E37: =+'Annexe 23'!G42 -> 4191.996 | F37: =+E37*0.1 -> 419.1996 | G37: =+E37-F37 -> 3772.7964
B38: =+'Annexe 26'!E11 -> 2026091 | C38: 46141 | D38: 2605429000035 | E38: =+'Annexe 26'!G41 -> 2160 | F38: =+E38*0.1 -> 216 | G38: =+E38-F38 -> 1944
B39: =+'Annexe 27'!E11 -> 2026092 | C39: 46141 | D39: 2605429000046 | E39: =+'Annexe 27'!G42 -> 3956.004 | F39: =+E39*0.1 -> 395.6004 | G39: =+E39-F39 -> 3560.4036
B40: =+'Annexe 28'!E11 -> 2026095 | C40: 46141 | D40: 2605429000062 | E40: =+'Annexe 28'!G43 -> 9943.2 | F40: =+E40*0.1 -> 994.32 | G40: =+E40-F40 -> 8948.88
B41: =+'Annexe 29'!E11 -> 20260101 | C41: 46141 | D41: 2605429000031 | E41: =+'Annexe 29'!G40 -> 8379.996 | F41: =+E41*0.1 -> 837.9996 | G41: =+E41-F41 -> 7541.9964
B42: =+'Annexe 30'!E11 -> 20260102 | C42: 46141 | D42: 2605429000068 | E42: =+'Annexe 30'!G40 -> 8379.996 | F42: =+E42*0.1 -> 837.9996 | G42: =+E42-F42 -> 7541.9964
B45: Total | E45: =SUM(E32:E44) -> 89395.26 | F45: =SUM(F32:F44) -> 8939.526 | G45: =SUM(G32:G44) -> 80455.734
E48: Cachet et Signature

Sheet Annexe 6 (1)
A1: MONSTER GARAGE
D11: Relevé des Factures | F11: Date: | G11: 46141
D13: A
C15: La Société Nationale des Transports et de la Logistique (SNTL)
B18: Partenaire
B19: N° Agrément SNTL | C19: 3108
B20: Raison Sociale | C20: WIDINE MOTORS SERVICES
B21: Adresse | C21: N°534 BIS 2 Q.I Sidi Ghanem
B22: Ville | C22: Marrakech
B23: RC | C23: 150241
B24: Patente | C24: 64006750
B25: IF | C25: 65976431
B26: ICE | C26: 003524622000063
B27: N° RIB | C27: 007450000612500000095129
B31: N° Facture | C31: Date facture | D31: N° Bon SNTL | E31: Montant TTC | F31: Commission SNTL | G31: Montant à régler
B32: =+'Annexe 7'!E11 -> 2026002 | C32: =+'Annexe 7'!G11 -> 46141 | D32: 260429000020 | E32: =+'Annexe 7'!G46 -> 2954.004 | F32: =+E32*0.1 -> 295.4004 | G32: =+E32-F32 -> 2658.6036
B33: =+'Annexe 8'!E11 -> 2026004 | C33: =+'Annexe 8'!G11 -> 46141 | D33: 260429000021 | E33: =+'Annexe 8'!G45 -> 9939.996 | F33: =+E33*0.1 -> 993.9996 | G33: =+E33-F33 -> 8945.9964
B34: =+'Annexe 10'!E11 -> 2026027 | C34: 46141 | D34: 260429000023 | E34: =+'Annexe 10'!G46 -> 15120 | F34: =+E34*0.1 -> 1512 | G34: =+E34-F34 -> 13608
B35: =+'Annexe 11'!E11 -> 2026032 | C35: 46141 | D35: 260429000043 | E35: =+'Annexe 11'!G46 -> 14466 | F35: =+E35*0.1 -> 1446.6 | G35: =+E35-F35 -> 13019.4
B36: =+'Annexe 12'!E11 -> 2026034 | C36: 46141 | D36: 260429000026 | E36: =+'Annexe 12'!G46 -> 7730.004 | F36: =+E36*0.1 -> 773.0004 | G36: =+E36-F36 -> 6957.0036
B37: =+'Annexe 13 '!E11 -> 2026049 | C37: 46141 | D37: 260429000027 | E37: =+'Annexe 13 '!G44 -> 3018 | F37: =+E37*0.1 -> 301.8 | G37: =+E37-F37 -> 2716.2
B38: =+'Annexe 14 '!E11 -> 2026050 | C38: 46141 | D38: 260429000028 | E38: =+'Annexe 14 '!G43 -> 1077 | F38: =+E38*0.1 -> 107.7 | G38: =+E38-F38 -> 969.3
B39: =+'Annexe 15'!E11 -> 2026053 | C39: 46141 | D39: 260429000038 | E39: =+'Annexe 15'!G46 -> 19616.004 | F39: =+E39*0.1 -> 1961.6004 | G39: =+E39-F39 -> 17654.404
B40: =+'Annexe 16 '!E11 -> 2026054 | C40: 46141 | D40: 260429000032 | E40: =+'Annexe 16 '!G43 -> 2280 | F40: =+E40*0.1 -> 228 | G40: =+E40-F40 -> 2052
B41: =+'Annexe 17'!E11 -> 2026072 | C41: 46141 | D41: 260429000040 | E41: =+'Annexe 17'!G43 -> 10740 | F41: =+E41*0.1 -> 1074 | G41: =+E41-F41 -> 9666
B44: Total | E44: 86941 | F44: =SUM(F32:F43) -> 8694.1008 | G44: 78246.9
E47: Cachet et Signature

Sheet Annexe 7
A1: MONSTER GARAGE
D11: Facture N° | E11: 2026002 | F11: Date facture: | G11: 46141
D13: A
C15: La Société Nationale des Transports et de la Logistique (SNTL)
B18: Partenaire | D18: Véhicule | F18: Partenaire
B19: N° Agrément SNTL | C19: =+'Annexe 6 (1)'!C19 -> 3108 | D19: Matricule | E19: 0207789 - J | F19: N° Accord SNTL
B20: Raison Sociale | C20: =+'Annexe 6 (1)'!C20 -> WIDINE MOTORS SERVICES | D20: Marque et modèle | E20: FORD TRANSIT
B21: Adresse | C21: =+'Annexe 6 (1)'!C21 -> N°534 BIS 2 Q.I Sidi Ghanem | D21: Kilométrage | E21: 332988
B22: Ville | C22: =+'Annexe 6 (1)'!C22 -> Marrakech | D22: Administration | E22: COMMUNE HARBIL
B23: RC | C23: =+'Annexe 6 (1)'!C23 -> 150241 | D23: N° de bon | E23: 260429000020
B24: Patente | C24: =+'Annexe 6 (1)'!C24 -> 64006750
B25: IF | C25: =+'Annexe 6 (1)'!C25 -> 65976431
B26: ICE | C26: =+'Annexe 6 (1)'!C26 -> 003524622000063
B27: N° RIB | C27: =+'Annexe 6 (1)'!C27 -> 007450000612500000095129
B31: Référence article | C31: Désignation Article | E31: Quantité | F31: PU HT | G31: Total HT
B32: REF - N001 | C32: PLAQUETTE DE FREIN ARRIERE | E32: 1 | F32: 874.5 | G32: =F32*E32 -> 874.5
B33: REF - N002 | C33: SOUFFLET CARDAN | E33: 1 | F33: 450.17 | G33: =F33*E33 -> 450.17
B34: REF - N003 | C34: HUILE DE FREIN | E34: 1 | F34: 185 | G34: =F34*E34 -> 185
B35: REF - N005 | C35: TEMOIN PLAQUETTE | E35: 1 | F35: 424 | G35: =F35*E35 -> 424
B42: Montant Total article HT | G42: =SUM(G32:G41) -> 1933.67
B43: Main d'œuvre* | G43: 528
B44: Montant Total article HT (1) | G44: =+G42+G43 -> 2461.67
B45: TVA 20% (2) | G45: =+G44*I45 -> 492.334 | I45: 0.2
B46: Montant Total TTC (1+2) (3) | G46: =+G44+G45 -> 2954.004
B47: Commission SNTL (1x10%) (4) | G47: =G44*I47 -> 246.167 | I47: 0.1
B48: TVA 20% sur la comission (4x20%) (5) | E48: Cachet et Signature | G48: =G47*I48 -> 49.2334 | I48: 0.2
B49: Montant Net à régler (3-4-5) | G49: =G46-G47-G48 -> 2658.6036
B51: Arrêté la présente facture à la somme de Deux mille six cent cinquante huit dirhams et soixante centimes TTC
E54: Cachet et signature
B59: * Non valable pour les bons ateliers ''A"

Sheet Annexe 8
A1: MONSTER GARAGE
D11: Facture N° | E11: 2026004 | F11: Date facture: | G11: 46141
D13: A
C15: La Société Nationale des Transports et de la Logistique (SNTL)
B18: Partenaire | D18: Véhicule | F18: Partenaire
B19: N° Agrément SNTL | C19: =+'Annexe 6 (1)'!C19 -> 3108 | D19: Matricule | E19: 0207789 - J | F19: N° Accord SNTL
B20: Raison Sociale | C20: =+'Annexe 6 (1)'!C20 -> WIDINE MOTORS SERVICES | D20: Marque et modèle | E20: FORD TRANSIT
B21: Adresse | C21: =+'Annexe 6 (1)'!C21 -> N°534 BIS 2 Q.I Sidi Ghanem | D21: Kilométrage | E21: 333212
B22: Ville | C22: =+'Annexe 6 (1)'!C22 -> Marrakech | D22: Administration | E22: COMMUNE HARBIL
B23: RC | C23: =+'Annexe 6 (1)'!C23 -> 150241 | D23: N° de bon | E23: 260429000021
B24: Patente | C24: =+'Annexe 6 (1)'!C24 -> 64006750
B25: IF | C25: =+'Annexe 6 (1)'!C25 -> 65976431
B26: ICE | C26: =+'Annexe 6 (1)'!C26 -> 003524622000063
B27: N° RIB | C27: =+'Annexe 6 (1)'!C27 -> 007450000612500000095129
B31: Référence article | C31: Désignation Article | E31: Quantité | F31: PU HT | G31: Total HT
B32: REF - N001 | C32: ROULEMENT MOYEU ARRIERE | E32: 1 | F32: 1074.5 | G32: =F32*E32 -> 1074.5
B33: REF - N002 | C33: MOYEU DE ROUE ARD | E33: 1 | F33: 3550.83 | G33: =F33*E33 -> 3550.83
B34: REF - N003 | C34: MONT / DEMONT PORTE FUSEE ARRIERE | E34: 1 | F34: 980 | G34: =F34*E34 -> 980
B35: REF - N004 | C35: REPARATION EMBRAYAGE | E35: 1 | F35: 850 | G35: =F35*E35 -> 850
B41: Montant Total article HT | G41: =SUM(G32:G40) -> 6455.33
B42: Main d'œuvre* | G42: 1828
B43: Montant Total article HT (1) | G43: =+G41+G42 -> 8283.33
B44: TVA 20% (2) | G44: =+G43*I44 -> 1656.666 | I44: 0.2
B45: Montant Total TTC (1+2) (3) | G45: =+G43+G44 -> 9939.996
B46: Commission SNTL (1x10%) (4) | G46: =G43*I46 -> 828.333 | I46: 0.1
B47: TVA 20% sur la comission (4x20%) (5) | E47: Cachet et Signature | G47: =G46*I47 -> 165.6666 | I47: 0.2
B48: Montant Net à régler (3-4-5) | G48: =G45-G46-G47 -> 8945.9964
B50: Arrêté la présente facture à la somme de Huit mille neuf cent quarante six dirhams TTC
E53: Cachet et signature
B58: * Non valable pour les bons ateliers ''A"

Sheet Annexe 9
A1: MONSTER GARAGE
D11: Facture N° | E11: 2026019 | F11: Date facture: | G11: 46140
D13: A
C15: La Société Nationale des Transports et de la Logistique (SNTL)
B18: Partenaire | D18: Véhicule | F18: Partenaire
B19: N° Agrément SNTL | C19: =+'Annexe 6 (1)'!C19 -> 3108 | D19: Matricule | E19: 207790 - J | F19: N° Accord SNTL
B20: Raison Sociale | C20: =+'Annexe 6 (1)'!C20 -> WIDINE MOTORS SERVICES | D20: Marque et modèle | E20: HYUNDAI ACCENT
B21: Adresse | C21: =+'Annexe 6 (1)'!C21 -> N°534 BIS 2 Q.I Sidi Ghanem | D21: Kilométrage | E21: 194427
B22: Ville | C22: =+'Annexe 6 (1)'!C22 -> Marrakech | D22: Administration | E22: COMMUNE HARBIL
B23: RC | C23: =+'Annexe 6 (1)'!C23 -> 150241 | D23: N° de bon | E23: 260126000007
B24: Patente | C24: =+'Annexe 6 (1)'!C24 -> 64006750
B25: IF | C25: =+'Annexe 6 (1)'!C25 -> 65976431
B26: ICE | C26: =+'Annexe 6 (1)'!C26 -> 003524622000063
B27: N° RIB | C27: =+'Annexe 6 (1)'!C27 -> 007450000612500000095129
B31: Référence article | C31: Désignation Article | E31: Quantité | F31: PU HT | G31: Total HT
B32: REF - N001 | C32: HUILE 5W30 | E32: 5 | F32: 125.4 | G32: =F32*E32 -> 627
B33: REF - N002 | C33: FILTRE A HUILE | E33: 1 | F33: 132 | G33: =F33*E33 -> 132
B34: REF - N003 | C34: FILTRE A AIR | E34: 1 | F34: 231 | G34: =F34*E34 -> 231
B35: REF - N004 | C35: FILTRE A GASOIL | E35: 1 | F35: 265 | G35: =F35*E35 -> 265
B36: REF - N005 | C36: FILTRE A POLLEN | E36: 1 | F36: 365 | G36: =F36*E36 -> 365
B37: REF - N006 | C37: GLACE RETROVISEUR GAUCHE | E37: 1 | F37: 550 | G37: =F37*E37 -> 550
B38: REF - N007 | C38: AMPOULE DE FREIN | E38: 3 | F38: 50 | G38: =F38*E38 -> 150
B39: REF - N008 | C39: AMPOULE DE MARCHE ARRIERE | E39: 2 | F39: 13.25 | G39: =F39*E39 -> 26.5
B40: REF - N009 | C40: AMPOULE FEU ANTIBROUILLARD GAUCHE | E40: 1 | F40: 82.67 | G40: =F40*E40 -> 82.67
B41: REF - N011 | C41: REPARATION MANNOT FREIN | E41: 1 | F41: 200 | G41: =F41*E41 -> 200
B42: Montant Total article HT | G42: =SUM(G32:G41) -> 2629.17
B43: Main d'œuvre* | G43: 500
B44: Montant Total article HT (1) | G44: =+G42+G43 -> 3129.17
B45: TVA 20% (2) | G45: =+G44*I45 -> 625.834 | I45: 0.2
B46: Montant Total TTC (1+2) (3) | G46: =+G44+G45 -> 3755.004
B47: Commission SNTL (1x10%) (4) | G47: =G44*I47 -> 312.917 | I47: 0.1
B48: TVA 20% sur la comission (4x20%) (5) | E48: Cachet et Signature | G48: =G47*I48 -> 62.5834 | I48: 0.2
B49: Montant Net à régler (3-4-5) | G49: =G46-G47-G48 -> 3379.5036
B51: Arrêté la présente facture à la somme de Trois mille trois cent soixante dix neuf dirhams et cinquante centimes TTC
E54: Cachet et signature
B59: * Non valable pour les bons ateliers ''A"

Sheet Annexe 10
A1: MONSTER GARAGE
D11: Facture N° | E11: 2026027 | F11: Date facture: | G11: 46141
D13: A
C15: La Société Nationale des Transports et de la Logistique (SNTL)
B18: Partenaire | D18: Véhicule | F18: Partenaire
B19: N° Agrément SNTL | C19: =+'Annexe 6 (1)'!C19 -> 3108 | D19: Matricule | E19: 0207789 - J | F19: N° Accord SNTL
B20: Raison Sociale | C20: =+'Annexe 6 (1)'!C20 -> WIDINE MOTORS SERVICES | D20: Marque et modèle | E20: FORD TRANSIT
B21: Adresse | C21: =+'Annexe 6 (1)'!C21 -> N°534 BIS 2 Q.I Sidi Ghanem | D21: Kilométrage | E21: 335243
B22: Ville | C22: =+'Annexe 6 (1)'!C22 -> Marrakech | D22: Administration | E22: COMMUNE HARBIL
B23: RC | C23: =+'Annexe 6 (1)'!C23 -> 150241 | D23: N° de bon | E23: 260429000023
B24: Patente | C24: =+'Annexe 6 (1)'!C24 -> 64006750
B25: IF | C25: =+'Annexe 6 (1)'!C25 -> 65976431
B26: ICE | C26: =+'Annexe 6 (1)'!C26 -> 003524622000063
B27: N° RIB | C27: =+'Annexe 6 (1)'!C27 -> 007450000612500000095129
B31: Référence article | C31: Désignation Article | E31: Quantité | F31: PU HT | G31: Total HT
B32: REF - N001 | C32: CARDAN | E32: 1 | F32: 7950 | G32: =F32*E32 -> 7950
B33: REF - N002 | C33: MONT / DEMONT PORTE FUSEE AVANT | E33: 2 | F33: 980 | G33: =F33*E33 -> 1960
B34: REF - N003 | C34: MONT / DEMONT CARDAN | E34: 1 | F34: 800 | G34: =F34*E34 -> 800
B35: REF - N004 | C35: DEGRIPPANT | E35: 1 | F35: 120 | G35: =F35*E35 -> 120
B36: REF - N005 | C36: PARRALLELISME | E36: 1 | F36: 120 | G36: =F36*E36 -> 120
B37: REF - N006 | C37: HUILE BOITE DE VITESSE | E37: 3 | F37: 150 | G37: =F37*E37 -> 450
B38: REF - N008 | C38: TOUR | E38: 4 | F38: 125 | G38: =F38*E38 -> 500
B42: Montant Total article HT | G42: =SUM(G32:G41) -> 11900
B43: Main d'œuvre* | G43: 700
B44: Montant Total article HT (1) | G44: =+G42+G43 -> 12600
B45: TVA 20% (2) | G45: =+G44*I45 -> 2520 | I45: 0.2
B46: Montant Total TTC (1+2) (3) | G46: =+G44+G45 -> 15120
B47: Commission SNTL (1x10%) (4) | G47: =G44*I47 -> 1260 | I47: 0.1
B48: TVA 20% sur la comission (4x20%) (5) | E48: Cachet et Signature | G48: =G47*I48 -> 252 | I48: 0.2
B49: Montant Net à régler (3-4-5) | G49: =G46-G47-G48 -> 13608
B51: Arrêté la présente facture à la somme de Treize mille six cent huit dirhams TTC
E54: Cachet et signature
B59: * Non valable pour les bons ateliers ''A"

Sheet Annexe 11
A1: MONSTER GARAGE
D11: Facture N° | E11: 2026032 | F11: Date facture: | G11: 46141
D13: A
C15: La Société Nationale des Transports et de la Logistique (SNTL)
B18: Partenaire | D18: Véhicule | F18: Partenaire
B19: N° Agrément SNTL | C19: =+'Annexe 6 (1)'!C19 -> 3108 | D19: Matricule | E19: 0215466 - J | F19: N° Accord SNTL
B20: Raison Sociale | C20: =+'Annexe 6 (1)'!C20 -> WIDINE MOTORS SERVICES | D20: Marque et modèle | E20: JCB ZX428 CHARGEUR
B21: Adresse | C21: =+'Annexe 6 (1)'!C21 -> N°534 BIS 2 Q.I Sidi Ghanem | D21: Kilométrage | E21: 4206
B22: Ville | C22: =+'Annexe 6 (1)'!C22 -> Marrakech | D22: Administration | E22: COMMUNE HARBIL
B23: RC | C23: =+'Annexe 6 (1)'!C23 -> 150241 | D23: N° de bon | E23: 260429000043
B24: Patente | C24: =+'Annexe 6 (1)'!C24 -> 64006750
B25: IF | C25: =+'Annexe 6 (1)'!C25 -> 65976431
B26: ICE | C26: =+'Annexe 6 (1)'!C26 -> 003524622000063
B27: N° RIB | C27: =+'Annexe 6 (1)'!C27 -> 007450000612500000095129
B31: Référence article | C31: Désignation Article | E31: Quantité | F31: PU HT | G31: Total HT
B32: REF - N001 | C32: PORTE SABOT | E32: 7 | F32: 1395 | G32: =F32*E32 -> 9765
B33: REF - N002 | C33: TOUR | E33: 7 | F33: 170 | G33: =F33*E33 -> 1190
B42: Montant Total article HT | G42: =SUM(G32:G41) -> 10955
B43: Main d'œuvre* | G43: 1100
B44: Montant Total article HT (1) | G44: =+G42+G43 -> 12055
B45: TVA 20% (2) | G45: =+G44*I45 -> 2411 | I45: 0.2
B46: Montant Total TTC (1+2) (3) | G46: =+G44+G45 -> 14466
B47: Commission SNTL (1x10%) (4) | G47: =G44*I47 -> 1205.5 | I47: 0.1
B48: TVA 20% sur la comission (4x20%) (5) | E48: Cachet et Signature | G48: =G47*I48 -> 241.1 | I48: 0.2
B49: Montant Net à régler (3-4-5) | G49: =G46-G47-G48 -> 13019.4
B51: Arrêté la présente facture à la somme de Treize mille dix neuf dirhams et quarante centimes TTC
E54: Cachet et signature
B59: * Non valable pour les bons ateliers ''A"

Sheet Annexe 12
A1: MONSTER GARAGE
D11: Facture N° | E11: 2026034 | F11: Date facture: | G11: 46141
D13: A
C15: La Société Nationale des Transports et de la Logistique (SNTL)
B18: Partenaire | D18: Véhicule | F18: Partenaire
B19: N° Agrément SNTL | C19: =+'Annexe 6 (1)'!C19 -> 3108 | D19: Matricule | E19: 0207789 - J | F19: N° Accord SNTL
B20: Raison Sociale | C20: =+'Annexe 6 (1)'!C20 -> WIDINE MOTORS SERVICES | D20: Marque et modèle | E20: FORD TRANSIT
B21: Adresse | C21: =+'Annexe 6 (1)'!C21 -> N°534 BIS 2 Q.I Sidi Ghanem | D21: Kilométrage | E21: 335708
B22: Ville | C22: =+'Annexe 6 (1)'!C22 -> Marrakech | D22: Administration | E22: COMMUNE HARBIL
B23: RC | C23: =+'Annexe 6 (1)'!C23 -> 150241 | D23: N° de bon | E23: 260429000026
B24: Patente | C24: =+'Annexe 6 (1)'!C24 -> 64006750
B25: IF | C25: =+'Annexe 6 (1)'!C25 -> 65976431
B26: ICE | C26: =+'Annexe 6 (1)'!C26 -> 003524622000063
B27: N° RIB | C27: =+'Annexe 6 (1)'!C27 -> 007450000612500000095129
B31: Référence article | C31: Désignation Article | E31: Quantité | F31: PU HT | G31: Total HT
B32: REF - N001 | C32: ROULEMENT AVANT GAUCHE | E32: 1 | F32: 1380 | G32: =F32*E32 -> 1380
B33: REF - N002 | C33: MOYEU DE ROUE AVG | E33: 1 | F33: 3657 | G33: =F33*E33 -> 3657
B34: REF - N003 | C34: MONT / DEMONT PORTE FUSEE AVG | E34: 1 | F34: 500 | G34: =F34*E34 -> 500
B35: REF - N004 | C35: MONT / DEMONT MOYEU DE ROUE AVG | E35: 1 | F35: 300 | G35: =F35*E35 -> 300
B36: REF - N005 | C36: DEGRIPPANT | E36: 1 | F36: 154.67 | G36: =F36*E36 -> 154.67
B37: REF - N006 | C37: PARRALLELISME | E37: 1 | F37: 150 | G37: =F37*E37 -> 150
B42: Montant Total article HT | G42: =SUM(G32:G41) -> 6141.67
B43: Main d'œuvre* | G43: 300
B44: Montant Total article HT (1) | G44: =+G42+G43 -> 6441.67
B45: TVA 20% (2) | G45: =+G44*I45 -> 1288.334 | I45: 0.2
B46: Montant Total TTC (1+2) (3) | G46: =+G44+G45 -> 7730.004
B47: Commission SNTL (1x10%) (4) | G47: =G44*I47 -> 644.167 | I47: 0.1
B48: TVA 20% sur la comission (4x20%) (5) | E48: Cachet et Signature | G48: =G47*I48 -> 128.8334 | I48: 0.2
B49: Montant Net à régler (3-4-5) | G49: =G46-G47-G48 -> 6957.0036
B51: Arrêté la présente facture à la somme de Six mille neuf cent cinquante sept dirhams TTC
E54: Cachet et signature
B59: * Non valable pour les bons ateliers ''A"

Sheet Annexe 13 
A1: MONSTER GARAGE
D11: Facture N° | E11: 2026049 | F11: Date facture: | G11: 46141
D13: A
C15: La Société Nationale des Transports et de la Logistique (SNTL)
B18: Partenaire | D18: Véhicule | F18: Partenaire
B19: N° Agrément SNTL | C19: =+'Annexe 6 (1)'!C19 -> 3108 | D19: Matricule | E19: 0207789 - J | F19: N° Accord SNTL
B20: Raison Sociale | C20: =+'Annexe 6 (1)'!C20 -> WIDINE MOTORS SERVICES | D20: Marque et modèle | E20: FORD TRANSIT
B21: Adresse | C21: =+'Annexe 6 (1)'!C21 -> N°534 BIS 2 Q.I Sidi Ghanem | D21: Kilométrage | E21: 336425
B22: Ville | C22: =+'Annexe 6 (1)'!C22 -> Marrakech | D22: Administration | E22: COMMUNE HARBIL
B23: RC | C23: =+'Annexe 6 (1)'!C23 -> 150241 | D23: N° de bon | E23: 260429000027
B24: Patente | C24: =+'Annexe 6 (1)'!C24 -> 64006750
B25: IF | C25: =+'Annexe 6 (1)'!C25 -> 65976431
B26: ICE | C26: =+'Annexe 6 (1)'!C26 -> 003524622000063
B27: N° RIB | C27: =+'Annexe 6 (1)'!C27 -> 007450000612500000095129
B31: Référence article | C31: Désignation Article | E31: Quantité | F31: PU HT | G31: Total HT
B32: REF - N001 | C32: KIT FLASHER AVANT | E32: 1 | F32: 465 | G32: =F32*E32 -> 465
B33: REF - N002 | C33: REPARATION CIRCUIT ELECTRIQUE | E33: 1 | F33: 800 | G33: =F33*E33 -> 800
B34: REF - N003 | C34: MONT / DEMONT TABLEAU DE BORD | E34: 1 | F34: 950 | G34: =F34*E34 -> 950
B40: Montant Total article HT | G40: =SUM(G32:G39) -> 2215
B41: Main d'œuvre* | G41: 300
B42: Montant Total article HT (1) | G42: =+G40+G41 -> 2515
B43: TVA 20% (2) | G43: =+G42*I43 -> 503 | I43: 0.2
B44: Montant Total TTC (1+2) (3) | G44: =+G42+G43 -> 3018
B45: Commission SNTL (1x10%) (4) | G45: =G42*I45 -> 251.5 | I45: 0.1
B46: TVA 20% sur la comission (4x20%) (5) | E46: Cachet et Signature | G46: =G45*I46 -> 50.3 | I46: 0.2
B47: Montant Net à régler (3-4-5) | G47: =G44-G45-G46 -> 2716.2
B49: Arrêté la présente facture à la somme de Deux mille sept cent seize dirhams et vingt centimes TTC
E52: Cachet et signature
B57: * Non valable pour les bons ateliers ''A"

Sheet Annexe 14 
A1: MONSTER GARAGE
D11: Facture N° | E11: 2026050 | F11: Date facture: | G11: 46141
D13: A
C15: La Société Nationale des Transports et de la Logistique (SNTL)
B18: Partenaire | D18: Véhicule | F18: Partenaire
B19: N° Agrément SNTL | C19: =+'Annexe 6 (1)'!C19 -> 3108 | D19: Matricule | E19: 0207789 - J | F19: N° Accord SNTL
B20: Raison Sociale | C20: =+'Annexe 6 (1)'!C20 -> WIDINE MOTORS SERVICES | D20: Marque et modèle | E20: FORD TRANSIT
B21: Adresse | C21: =+'Annexe 6 (1)'!C21 -> N°534 BIS 2 Q.I Sidi Ghanem | D21: Kilométrage | E21: 336615
B22: Ville | C22: =+'Annexe 6 (1)'!C22 -> Marrakech | D22: Administration | E22: COMMUNE HARBIL
B23: RC | C23: =+'Annexe 6 (1)'!C23 -> 150241 | D23: N° de bon | E23: 260429000028
B24: Patente | C24: =+'Annexe 6 (1)'!C24 -> 64006750
B25: IF | C25: =+'Annexe 6 (1)'!C25 -> 65976431
B26: ICE | C26: =+'Annexe 6 (1)'!C26 -> 003524622000063
B27: N° RIB | C27: =+'Annexe 6 (1)'!C27 -> 007450000612500000095129
B31: Référence article | C31: Désignation Article | E31: Quantité | F31: PU HT | G31: Total HT
B32: REF - N001 | C32: GLACE RETROVISEUR DROITE | E32: 1 | F32: 547.5 | G32: =F32*E32 -> 547.5
B33: REF - N002 | C33: REPARATION CIRCUIT ELECTRIQUE | E33: 1 | F33: 150 | G33: =F33*E33 -> 150
B39: Montant Total article HT | G39: =SUM(G32:G38) -> 697.5
B40: Main d'œuvre* | G40: 200
B41: Montant Total article HT (1) | G41: =+G39+G40 -> 897.5
B42: TVA 20% (2) | G42: =+G41*I42 -> 179.5 | I42: 0.2
B43: Montant Total TTC (1+2) (3) | G43: =+G41+G42 -> 1077
B44: Commission SNTL (1x10%) (4) | G44: =G41*I44 -> 89.75 | I44: 0.1
B45: TVA 20% sur la comission (4x20%) (5) | E45: Cachet et Signature | G45: =G44*I45 -> 17.95 | I45: 0.2
B46: Montant Net à régler (3-4-5) | G46: =G43-G44-G45 -> 969.3
B48: Arrêté la présente facture à la somme de Neuf cent soixante neuf dirhams et trente centimes TTC
E51: Cachet et signature
B56: * Non valable pour les bons ateliers ''A"

Sheet Annexe 15
A1: MONSTER GARAGE
D11: Facture N° | E11: 2026053 | F11: Date facture: | G11: 46141
D13: A
C15: La Société Nationale des Transports et de la Logistique (SNTL)
B18: Partenaire | D18: Véhicule | F18: Partenaire
B19: N° Agrément SNTL | C19: =+'Annexe 6 (1)'!C19 -> 3108 | D19: Matricule | E19: 0257528- J | F19: N° Accord SNTL
B20: Raison Sociale | C20: =+'Annexe 6 (1)'!C20 -> WIDINE MOTORS SERVICES | D20: Marque et modèle | E20: RENAULT MASTER
B21: Adresse | C21: =+'Annexe 6 (1)'!C21 -> N°534 BIS 2 Q.I Sidi Ghanem | D21: Kilométrage | E21: 49821
B22: Ville | C22: =+'Annexe 6 (1)'!C22 -> Marrakech | D22: Administration | E22: COMMUNE HARBIL
B23: RC | C23: =+'Annexe 6 (1)'!C23 -> 150241 | D23: N° de bon | E23: 260429000038
B24: Patente | C24: =+'Annexe 6 (1)'!C24 -> 64006750
B25: IF | C25: =+'Annexe 6 (1)'!C25 -> 65976431
B26: ICE | C26: =+'Annexe 6 (1)'!C26 -> 003524622000063
B27: N° RIB | C27: =+'Annexe 6 (1)'!C27 -> 007450000612500000095129
B31: Référence article | C31: Désignation Article | E31: Quantité | F31: PU HT | G31: Total HT
B32: REF - N001 | C32: PLAQUETTE DE FREIN AVANT | E32: 1 | F32: 1533 | G32: =F32*E32 -> 1533
B33: REF - N002 | C33: PLAQUETTE DE FREIN ARRIERE | E33: 1 | F33: 1314 | G33: =F33*E33 -> 1314
B34: REF - N003 | C34: CAPTEUR D'USURE AVANT | E34: 1 | F34: 90 | G34: =F34*E34 -> 90
B35: REF - N004 | C35: CAPTEUR D'USURE ARRIERE | E35: 1 | F35: 90 | G35: =F35*E35 -> 90
B36: REF - N005 | C36: HUILE BOITE DE VITESSE | E36: 3 | F36: 450 | G36: =F36*E36 -> 1350
B37: REF - N006 | C37: CARDAN | E37: 1 | F37: 8890 | G37: =F37*E37 -> 8890
B38: REF - N007 | C38: MONT / DEMONT CARDAN | E38: 1 | F38: 980 | G38: =F38*E38 -> 980
B39: REF - N008 | C39: MONT / DEMONT PORTE FUSEE AVANT | E39: 1 | F39: 799.67 | G39: =F39*E39 -> 799.67
B40: REF - N009 | C40: TOUR | E40: 4 | F40: 125 | G40: =F40*E40 -> 500
B42: Montant Total article HT | G42: =SUM(G32:G41) -> 15546.67
B43: Main d'œuvre* | G43: 800
B44: Montant Total article HT (1) | G44: =+G42+G43 -> 16346.67
B45: TVA 20% (2) | G45: =+G44*I45 -> 3269.334 | I45: 0.2
B46: Montant Total TTC (1+2) (3) | G46: =+G44+G45 -> 19616.004
B47: Commission SNTL (1x10%) (4) | G47: =G44*I47 -> 1634.667 | I47: 0.1
B48: TVA 20% sur la comission (4x20%) (5) | E48: Cachet et Signature | G48: =G47*I48 -> 326.9334 | I48: 0.2
B49: Montant Net à régler (3-4-5) | G49: =G46-G47-G48 -> 17654.404
B51: Arrêté la présente facture à la somme de Dix sept mille six cent cinquante quatre dirhams et quarante centimes TTC
E54: Cachet et signature
B59: * Non valable pour les bons ateliers ''A"

Sheet Annexe 16 
A1: MONSTER GARAGE
D11: Facture N° | E11: 2026054 | F11: Date facture: | G11: 46141
D13: A
C15: La Société Nationale des Transports et de la Logistique (SNTL)
B18: Partenaire | D18: Véhicule | F18: Partenaire
B19: N° Agrément SNTL | C19: =+'Annexe 6 (1)'!C19 -> 3108 | D19: Matricule | E19: 0219569 - J | F19: N° Accord SNTL
B20: Raison Sociale | C20: =+'Annexe 6 (1)'!C20 -> WIDINE MOTORS SERVICES | D20: Marque et modèle | E20: MITSUBISHI PAJERO
B21: Adresse | C21: =+'Annexe 6 (1)'!C21 -> N°534 BIS 2 Q.I Sidi Ghanem | D21: Kilométrage | E21: 208797
B22: Ville | C22: =+'Annexe 6 (1)'!C22 -> Marrakech | D22: Administration | E22: COMMUNE HARBIL
B23: RC | C23: =+'Annexe 6 (1)'!C23 -> 150241 | D23: N° de bon | E23: 260429000032
B24: Patente | C24: =+'Annexe 6 (1)'!C24 -> 64006750
B25: IF | C25: =+'Annexe 6 (1)'!C25 -> 65976431
B26: ICE | C26: =+'Annexe 6 (1)'!C26 -> 003524622000063
B27: N° RIB | C27: =+'Annexe 6 (1)'!C27 -> 007450000612500000095129
B31: Référence article | C31: Désignation Article | E31: Quantité | F31: PU HT | G31: Total HT
B32: REF - N001 | C32: KIT AMPOULE LED | E32: 2 | F32: 665 | G32: =F32*E32 -> 1330
B33: REF - N002 | C33: MONT / DEMONT PARE CHOC AVANT | E33: 1 | F33: 420 | G33: =F33*E33 -> 420
B39: Montant Total article HT | G39: =SUM(G32:G38) -> 1750
B40: Main d'œuvre* | G40: 150
B41: Montant Total article HT (1) | G41: =+G39+G40 -> 1900
B42: TVA 20% (2) | G42: =+G41*I42 -> 380 | I42: 0.2
B43: Montant Total TTC (1+2) (3) | G43: =+G41+G42 -> 2280
B44: Commission SNTL (1x10%) (4) | G44: =G41*I44 -> 190 | I44: 0.1
B45: TVA 20% sur la comission (4x20%) (5) | E45: Cachet et Signature | G45: =G44*I45 -> 38 | I45: 0.2
B46: Montant Net à régler (3-4-5) | G46: =G43-G44-G45 -> 2052
B48: Arrêté la présente facture à la somme de Deux mille cinquante deux dirhams TTC
E51: Cachet et signature
B56: * Non valable pour les bons ateliers ''A"

Sheet Annexe 17
A1: MONSTER GARAGE
D11: Facture N° | E11: 2026072 | F11: Date facture: | G11: 46141
D13: A
C15: La Société Nationale des Transports et de la Logistique (SNTL)
B18: Partenaire | D18: Véhicule | F18: Partenaire
B19: N° Agrément SNTL | C19: =+'Annexe 6 (1)'!C19 -> 3108 | D19: Matricule | E19: 0207799- J | F19: N° Accord SNTL
B20: Raison Sociale | C20: =+'Annexe 6 (1)'!C20 -> WIDINE MOTORS SERVICES | D20: Marque et modèle | E20: MITSUBISHI FUSO
B21: Adresse | C21: =+'Annexe 6 (1)'!C21 -> N°534 BIS 2 Q.I Sidi Ghanem | D21: Kilométrage | E21: 53199
B22: Ville | C22: =+'Annexe 6 (1)'!C22 -> Marrakech | D22: Administration | E22: COMMUNE HARBIL
B23: RC | C23: =+'Annexe 6 (1)'!C23 -> 150241 | D23: N° de bon | E23: 260429000040
B24: Patente | C24: =+'Annexe 6 (1)'!C24 -> 64006750
B25: IF | C25: =+'Annexe 6 (1)'!C25 -> 65976431
B26: ICE | C26: =+'Annexe 6 (1)'!C26 -> 003524622000063
B27: N° RIB | C27: =+'Annexe 6 (1)'!C27 -> 007450000612500000095129
B31: Référence article | C31: Désignation Article | E31: Quantité | F31: PU HT | G31: Total HT
B32: REF - N001 | C32: BATTERIE L3 VARTA SILVER | E32: 1 | F32: 3050 | G32: =F32*E32 -> 3050
B33: REF - N002 | C33: BATTERIE L5 VARTA SILVER | E33: 1 | F33: 5400 | G33: =F33*E33 -> 5400
B39: Montant Total article HT | G39: =SUM(G32:G38) -> 8450
B40: Main d'œuvre* | G40: 500
B41: Montant Total article HT (1) | G41: =+G39+G40 -> 8950
B42: TVA 20% (2) | G42: =+G41*I42 -> 1790 | I42: 0.2
B43: Montant Total TTC (1+2) (3) | G43: =+G41+G42 -> 10740
B44: Commission SNTL (1x10%) (4) | G44: =G41*I44 -> 895 | I44: 0.1
B45: TVA 20% sur la comission (4x20%) (5) | E45: Cachet et Signature | G45: =G44*I45 -> 179 | I45: 0.2
B46: Montant Net à régler (3-4-5) | G46: =G43-G44-G45 -> 9666
B48: Arrêté la présente facture à la somme de Neuf mille six cent soixante six dirhams TTC
E51: Cachet et signature
B56: * Non valable pour les bons ateliers ''A"

Sheet Annexe 18
A1: MONSTER GARAGE
D11: Facture N° | E11: 2026075 | F11: Date facture: | G11: 46141
D13: A
C15: La Société Nationale des Transports et de la Logistique (SNTL)
B18: Partenaire | D18: Véhicule | F18: Partenaire
B19: N° Agrément SNTL | C19: =+'Annexe 6 (1)'!C19 -> 3108 | D19: Matricule | E19: 0207789 - J | F19: N° Accord SNTL
B20: Raison Sociale | C20: =+'Annexe 6 (1)'!C20 -> WIDINE MOTORS SERVICES | D20: Marque et modèle | E20: FORD TRANSIT
B21: Adresse | C21: =+'Annexe 6 (1)'!C21 -> N°534 BIS 2 Q.I Sidi Ghanem | D21: Kilométrage | E21: 339402
B22: Ville | C22: =+'Annexe 6 (1)'!C22 -> Marrakech | D22: Administration | E22: COMMUNE HARBIL
B23: RC | C23: =+'Annexe 6 (1)'!C23 -> 150241 | D23: N° de bon | E23: 260429000029
B24: Patente | C24: =+'Annexe 6 (1)'!C24 -> 64006750
B25: IF | C25: =+'Annexe 6 (1)'!C25 -> 65976431
B26: ICE | C26: =+'Annexe 6 (1)'!C26 -> 003524622000063
B27: N° RIB | C27: =+'Annexe 6 (1)'!C27 -> 007450000612500000095129
B31: Référence article | C31: Désignation Article | E31: Quantité | F31: PU HT | G31: Total HT
B32: REF - N001 | C32: MONT / DEMONT PLAFOND ARRIERE | E32: 1 | F32: 800 | G32: =F32*E32 -> 800
B33: REF - N002 | C33: MONT / DEMONT GARNITURE PORTE COULISSANTE | E33: 1 | F33: 400 | G33: =F33*E33 -> 400
B34: REF - N003 | C34: REPARATION COURT - CIRCUIT | E34: 2 | F34: 300 | G34: =F34*E34 -> 600
B40: Montant Total article HT | G40: =SUM(G32:G39) -> 1800
B41: Main d'œuvre* | G41: 100
B42: Montant Total article HT (1) | G42: =+G40+G41 -> 1900
B43: TVA 20% (2) | G43: =+G42*I43 -> 380 | I43: 0.2
B44: Montant Total TTC (1+2) (3) | G44: =+G42+G43 -> 2280
B45: Commission SNTL (1x10%) (4) | G45: =G42*I45 -> 190 | I45: 0.1
B46: TVA 20% sur la comission (4x20%) (5) | E46: Cachet et Signature | G46: =G45*I46 -> 38 | I46: 0.2
B47: Montant Net à régler (3-4-5) | G47: =G44-G45-G46 -> 2052
B49: Arrêté la présente facture à la somme de Deux mille cinquante deux dirhams TTC
E52: Cachet et signature
B57: * Non valable pour les bons ateliers ''A"

Sheet Annexe 19
A1: MONSTER GARAGE
D11: Facture N° | E11: 2026076 | F11: Date facture: | G11: 46141
D13: A
C15: La Société Nationale des Transports et de la Logistique (SNTL)
B18: Partenaire | D18: Véhicule | F18: Partenaire
B19: N° Agrément SNTL | C19: =+'Annexe 6 (1)'!C19 -> 3108 | D19: Matricule | E19: 0242298 - J | F19: N° Accord SNTL
B20: Raison Sociale | C20: =+'Annexe 6 (1)'!C20 -> WIDINE MOTORS SERVICES | D20: Marque et modèle | E20: HYUNDAI HD65
B21: Adresse | C21: =+'Annexe 6 (1)'!C21 -> N°534 BIS 2 Q.I Sidi Ghanem | D21: Kilométrage | E21: 85036
B22: Ville | C22: =+'Annexe 6 (1)'!C22 -> Marrakech | D22: Administration | E22: COMMUNE HARBIL
B23: RC | C23: =+'Annexe 6 (1)'!C23 -> 150241 | D23: N° de bon | E23: 260429000067
B24: Patente | C24: =+'Annexe 6 (1)'!C24 -> 64006750
B25: IF | C25: =+'Annexe 6 (1)'!C25 -> 65976431
B26: ICE | C26: =+'Annexe 6 (1)'!C26 -> 003524622000063
B27: N° RIB | C27: =+'Annexe 6 (1)'!C27 -> 007450000612500000095129
B31: Référence article | C31: Désignation Article | E31: Quantité | F31: PU HT | G31: Total HT
B32: REF - N001 | C32: MONT / DEMONT COMBINE INSTRUMENTS | E32: 1 | F32: 800 | G32: =F32*E32 -> 800
B33: REF - N002 | C33: REPARATION COMBINE INSTRUMENTS | E33: 1 | F33: 300 | G33: =F33*E33 -> 300
B39: Montant Total article HT | G39: =SUM(G32:G38) -> 1100
B40: Main d'œuvre* | G40: 500
B41: Montant Total article HT (1) | G41: =+G39+G40 -> 1600
B42: TVA 20% (2) | G42: =+G41*I42 -> 320 | I42: 0.2
B43: Montant Total TTC (1+2) (3) | G43: =+G41+G42 -> 1920
B44: Commission SNTL (1x10%) (4) | G44: =G41*I44 -> 160 | I44: 0.1
B45: TVA 20% sur la comission (4x20%) (5) | E45: Cachet et Signature | G45: =G44*I45 -> 32 | I45: 0.2
B46: Montant Net à régler (3-4-5) | G46: =G43-G44-G45 -> 1728
B48: Arrêté la présente facture à la somme de Mille sept cent vingt huit dirhams TTC
E51: Cachet et signature
B56: * Non valable pour les bons ateliers ''A"

Sheet Annexe 20
A1: MONSTER GARAGE
D11: Facture N° | E11: 2026074 | F11: Date facture: | G11: 46141
D13: A
C15: La Société Nationale des Transports et de la Logistique (SNTL)
B18: Partenaire | D18: Véhicule | F18: Partenaire
B19: N° Agrément SNTL | C19: =+'Annexe 6 (1)'!C19 -> 3108 | D19: Matricule | E19: 0207799 - J | F19: N° Accord SNTL
B20: Raison Sociale | C20: =+'Annexe 6 (1)'!C20 -> WIDINE MOTORS SERVICES | D20: Marque et modèle | E20: MITSUBISHI FUSO
B21: Adresse | C21: =+'Annexe 6 (1)'!C21 -> N°534 BIS 2 Q.I Sidi Ghanem | D21: Kilométrage | E21: 53425
B22: Ville | C22: =+'Annexe 6 (1)'!C22 -> Marrakech | D22: Administration | E22: COMMUNE HARBIL
B23: RC | C23: =+'Annexe 6 (1)'!C23 -> 150241 | D23: N° de bon | E23: 260429000041
B24: Patente | C24: =+'Annexe 6 (1)'!C24 -> 64006750
B25: IF | C25: =+'Annexe 6 (1)'!C25 -> 65976431
B26: ICE | C26: =+'Annexe 6 (1)'!C26 -> 003524622000063
B27: N° RIB | C27: =+'Annexe 6 (1)'!C27 -> 007450000612500000095129
B31: Référence article | C31: Désignation Article | E31: Quantité | F31: PU HT | G31: Total HT
B32: REF - N001 | C32: HUILE BOITE DE VITESSE | E32: 5 | F32: 222 | G32: =F32*E32 -> 1110
B33: REF - N002 | C33: SILENT BLOCK AVANT | E33: 2 | F33: 1320 | G33: =F33*E33 -> 2640
B34: REF - N003 | C34: ROTULES AVANT | E34: 2 | F34: 2344.585 | G34: =F34*E34 -> 4689.17
B35: REF - N004 | C35: MONT / DEMONT TRAIN AVANT | E35: 1 | F35: 1100 | G35: =F35*E35 -> 1100
B36: REF - N005 | C36: KIT EMBRAYAGE | E36: 1 | F36: 4650 | G36: =F36*E36 -> 4650
B37: REF - N006 | C37: REPARATION SERRURES | E37: 2 | F37: 150 | G37: =F37*E37 -> 300
B38: Montant Total article HT | G38: =SUM(G32:G37) -> 14489.17
B39: Main d'œuvre* | G39: 2000
B40: Montant Total article HT (1) | G40: =+G38+G39 -> 16489.17
B41: TVA 20% (2) | G41: =+G40*I41 -> 3297.834 | I41: 0.2
B42: Montant Total TTC (1+2) (3) | G42: =+G40+G41 -> 19787.004
B43: Commission SNTL (1x10%) (4) | G43: =G40*I43 -> 1648.917 | I43: 0.1
B44: TVA 20% sur la comission (4x20%) (5) | E44: Cachet et Signature | G44: =G43*I44 -> 329.7834 | I44: 0.2
B45: Montant Net à régler (3-4-5) | G45: =G42-G43-G44 -> 17808.304
B47: Arrêté la présente facture à la somme de Dix sept mille huit cent huit dirhams et trente centimes TTC
E50: Cachet et signature
B55: * Non valable pour les bons ateliers ''A"

Sheet Annexe 21
A1: MONSTER GARAGE
D11: Facture N° | E11: 2026082 | F11: Date facture: | G11: 46141
D13: A
C15: La Société Nationale des Transports et de la Logistique (SNTL)
B18: Partenaire | D18: Véhicule | F18: Partenaire
B19: N° Agrément SNTL | C19: =+'Annexe 6 (1)'!C19 -> 3108 | D19: Matricule | E19: 0219569- J | F19: N° Accord SNTL
B20: Raison Sociale | C20: =+'Annexe 6 (1)'!C20 -> WIDINE MOTORS SERVICES | D20: Marque et modèle | E20: MITSUBISHI PAJERO
B21: Adresse | C21: =+'Annexe 6 (1)'!C21 -> N°534 BIS 2 Q.I Sidi Ghanem | D21: Kilométrage | E21: 209485
B22: Ville | C22: =+'Annexe 6 (1)'!C22 -> Marrakech | D22: Administration | E22: COMMUNE HARBIL
B23: RC | C23: =+'Annexe 6 (1)'!C23 -> 150241 | D23: N° de bon | E23: 260429000034
B24: Patente | C24: =+'Annexe 6 (1)'!C24 -> 64006750
B25: IF | C25: =+'Annexe 6 (1)'!C25 -> 65976431
B26: ICE | C26: =+'Annexe 6 (1)'!C26 -> 003524622000063
B27: N° RIB | C27: =+'Annexe 6 (1)'!C27 -> 007450000612500000095129
B31: Référence article | C31: Désignation Article | E31: Quantité | F31: PU HT | G31: Total HT
B32: REF - N001 | C32: HUILE MOTEUR 5W30 | E32: 7 | F32: 120 | G32: =F32*E32 -> 840
B33: REF - N002 | C33: FILTRE A HUILE | E33: 1 | F33: 159 | G33: =F33*E33 -> 159
B34: REF - N003 | C34: FILTRE A GASOIL | E34: 1 | F34: 219 | G34: =F34*E34 -> 219
B35: REF - N004 | C35: FILTRE A AIR | E35: 1 | F35: 438 | G35: =F35*E35 -> 438
B36: REF - N005 | C36: REPARATION FEUX TOURNANTS | E36: 1 | F36: 450 | G36: =F36*E36 -> 450
B37: REF - N006 | C37: PLAQUETTES DE FREIN AVANT | E37: 1 | F37: 689 | G37: =F37*E37 -> 689
B38: REF - N007 | C38: BIELETTE DE SUSPENSION G-D | E38: 2 | F38: 757.9 | G38: =F38*E38 -> 1515.8
B39: REF - N008 | C39: ROTULE DROITE | E39: 1 | F39: 954 | G39: =F39*E39 -> 954
B40: REF - N009 | C40: REPARATION OPTIQUES AVANT | E40: 2 | F40: 300 | G40: =F40*E40 -> 600
B41: REF - N012 | C41: EAU LAVE GLACE | E41: 5 | F41: 20 | G41: =F41*E41 -> 100
B42: REF - N013 | C42: EAU ANTIGEL | E42: 5 | F42: 20 | G42: =F42*E42 -> 100
B43: REF - N014 | C43: SILENT BLOCK GAUCHE | E43: 1 | F43: 583 | G43: =F43*E43 -> 583
... B47: REF - N018 | C47: LAVAGE EXTERIEUR + MOTEUR | E47: 1 | F47: 40 | G47: =F47*E47 -> 40
G48: =SUM(G32:G47) -> 8729.4
B49: Main d'œuvre* | G49: 1450.17
B50: Montant Total article HT (1) | G50: =+G48+G49 -> 10179.57
B51: TVA 20% (2) | G51: =+G50*I51 -> 2035.914 | I51: 0.2
B52: Montant Total TTC (1+2) (3) | G52: =+G50+G51 -> 12215.484
B53: Commission SNTL (1x10%) (4) | G53: =G50*I53 -> 1017.957 | I53: 0.1
B54: TVA 20% sur la comission (4x20%) (5) | E54: Cachet et Signature | G54: =G53*I54 -> 203.5914 | I54: 0.2
B55: Montant Net à régler (3-4-5) | G55: =G52-G53-G54 -> 10993.936
B57: Arrêté la présente facture à la somme de Dix mille neuf cent quatre vingt treize dirhams et quatre vingt quatorze centimes TTC
E60: Cachet et signature
B65: * Non valable pour les bons ateliers ''A"

Sheet Annexe 22 
A1: MONSTER GARAGE
D11: Facture N° | E11: 2026079 | F11: Date facture: | G11: 46141
D13: A
C15: La Société Nationale des Transports et de la Logistique (SNTL)
B18: Partenaire | D18: Véhicule | F18: Partenaire
B19: N° Agrément SNTL | C19: =+'Annexe 6 (1)'!C19 -> 3108 | D19: Matricule | E19: 0219569 - J | F19: N° Accord SNTL
B20: Raison Sociale | C20: =+'Annexe 6 (1)'!C20 -> WIDINE MOTORS SERVICES | D20: Marque et modèle | E20: MITSUBISHI PAJERO SP
B21: Adresse | C21: =+'Annexe 6 (1)'!C21 -> N°534 BIS 2 Q.I Sidi Ghanem | D21: Kilométrage | E21: 209449
B22: Ville | C22: =+'Annexe 6 (1)'!C22 -> Marrakech | D22: Administration | E22: COMMUNE HARBIL
B23: RC | C23: =+'Annexe 6 (1)'!C23 -> 150241 | D23: N° de bon | E23: 260429000033
B24: Patente | C24: =+'Annexe 6 (1)'!C24 -> 64006750
B25: IF | C25: =+'Annexe 6 (1)'!C25 -> 65976431
B26: ICE | C26: =+'Annexe 6 (1)'!C26 -> 003524622000063
B27: N° RIB | C27: =+'Annexe 6 (1)'!C27 -> 007450000612500000095129
B31: Référence article | C31: Désignation Article | E31: Quantité | F31: PU HT | G31: Total HT
B32: REF - N001 | C32: KIT EMBRAYAGE | E32: 1 | F32: 6717.15 | G32: =F32*E32 -> 6717.15
B33: REF - N002 | C33: BUTIL | E33: 1 | F33: 2517.5 | G33: =F33*E33 -> 2517.5
B34: REF - N003 | C34: DURITE TURBO SUPERIEURE | E34: 1 | F34: 2650 | G34: =F34*E34 -> 2650
B39: Montant Total article HT | G39: =SUM(G32:G38) -> 11884.65
B40: Main d'œuvre* | G40: 1600
B41: Montant Total article HT (1) | G41: =+G39+G40 -> 13484.65
B42: TVA 20% (2) | G42: =+G41*I42 -> 2696.93 | I42: 0.2
B43: Montant Total TTC (1+2) (3) | G43: =+G41+G42 -> 16181.58
B44: Commission SNTL (1x10%) (4) | G44: =G41*I44 -> 1348.465 | I44: 0.1
B45: TVA 20% sur la comission (4x20%) (5) | E45: Cachet et Signature | G45: =G44*I45 -> 269.693 | I45: 0.2
B46: Montant Net à régler (3-4-5) | G46: =G43-G44-G45 -> 14563.422
B48: Arrêté la présente facture à la somme de Quatorze mille cinq cent soixante trois dirhams et quarante deux centimes TTC
E51: Cachet et signature
B56: * Non valable pour les bons ateliers ''A"

Sheet Annexe 23
A1: MONSTER GARAGE
D11: Facture N° | E11: 2026080 | F11: Date facture: | G11: 46141
D13: A
C15: La Société Nationale des Transports et de la Logistique (SNTL)
B18: Partenaire | D18: Véhicule | F18: Partenaire
B19: N° Agrément SNTL | C19: =+'Annexe 6 (1)'!C19 -> 3108 | D19: Matricule | E19: 0207789 - J | F19: N° Accord SNTL
B20: Raison Sociale | C20: =+'Annexe 6 (1)'!C20 -> WIDINE MOTORS SERVICES | D20: Marque et modèle | E20: FORD TRANSIT AMB
B21: Adresse | C21: =+'Annexe 6 (1)'!C21 -> N°534 BIS 2 Q.I Sidi Ghanem | D21: Kilométrage | E21: 341070
B22: Ville | C22: =+'Annexe 6 (1)'!C22 -> Marrakech | D22: Administration | E22: COMMUNE HARBIL
B23: RC | C23: =+'Annexe 6 (1)'!C23 -> 150241 | D23: N° de bon | E23: 260429000030
B24: Patente | C24: =+'Annexe 6 (1)'!C24 -> 64006750
B25: IF | C25: =+'Annexe 6 (1)'!C25 -> 65976431
B26: ICE | C26: =+'Annexe 6 (1)'!C26 -> 003524622000063
B27: N° RIB | C27: =+'Annexe 6 (1)'!C27 -> 007450000612500000095129
B31: Référence article | C31: Désignation Article | E31: Quantité | F31: PU HT | G31: Total HT
B32: REF - N001 | C32: HUILE MOTEUR 5W30 | E32: 8 | F32: 195 | G32: =F32*E32 -> 1560
B33: REF - N002 | C33: FILTRE A HUILE | E33: 1 | F33: 230.64 | G33: =F33*E33 -> 230.64
B34: REF - N003 | C34: FILTRE A AIR | E34: 1 | F34: 627.69 | G34: =F34*E34 -> 627.69
B35: REF - N004 | C35: AMPOULES | E35: 5 | F35: 85 | G35: =F35*E35 -> 425
B36: REF - N005 | C36: REPARATION COURT CIRCUIT FEU ARR | E36: 2 | F36: 100 | G36: =F36*E36 -> 200
B38: Montant Total article HT | G38: =SUM(G32:G37) -> 3043.33
B39: Main d'œuvre* | G39: 450
B40: Montant Total article HT (1) | G40: =+G38+G39 -> 3493.33
B41: TVA 20% (2) | G41: =+G40*I41 -> 698.666 | I41: 0.2
B42: Montant Total TTC (1+2) (3) | G42: =+G40+G41 -> 4191.996
B43: Commission SNTL (1x10%) (4) | G43: =G40*I43 -> 349.333 | I43: 0.1
B44: TVA 20% sur la comission (4x20%) (5) | E44: Cachet et Signature | G44: =G43*I44 -> 69.8666 | I44: 0.2
B45: Montant Net à régler (3-4-5) | G45: =G42-G43-G44 -> 3772.7964
B47: Arrêté la présente facture à la somme de Trois mille sept cent soixante douze dirhams et quatre vingt centimes TTC
E50: Cachet et signature
B55: * Non valable pour les bons ateliers ''A"

Sheet Annexe 24
A1: MONSTER GARAGE
D11: Facture N° | E11: 2026085 | F11: Date facture: | G11: 46140
D13: A
C15: La Société Nationale des Transports et de la Logistique (SNTL)
B18: Partenaire | D18: Véhicule | F18: Partenaire
B19: N° Agrément SNTL | C19: =+'Annexe 6 (1)'!C19 -> 3108 | D19: Matricule | E19: 202955 - J | F19: N° Accord SNTL
B20: Raison Sociale | C20: =+'Annexe 6 (1)'!C20 -> WIDINE MOTORS SERVICES | D20: Marque et modèle | E20: HYUNDAI I40
B21: Adresse | C21: =+'Annexe 6 (1)'!C21 -> N°534 BIS 2 Q.I Sidi Ghanem | D21: Kilométrage | E21: 203499
B22: Ville | C22: =+'Annexe 6 (1)'!C22 -> Marrakech | D22: Administration | E22: COMMUNE HARBIL
B23: RC | C23: =+'Annexe 6 (1)'!C23 -> 150241 | D23: N° de bon | E23: 260126000024
B24: Patente | C24: =+'Annexe 6 (1)'!C24 -> 64006750
B25: IF | C25: =+'Annexe 6 (1)'!C25 -> 65976431
B26: ICE | C26: =+'Annexe 6 (1)'!C26 -> 003524622000063
B27: N° RIB | C27: =+'Annexe 6 (1)'!C27 -> 007450000612500000095129
B31: Référence article | C31: Désignation Article | E31: Quantité | F31: PU HT | G31: Total HT
B32: REF - N001 | C32: HUILE MOTEUR 5W30 | E32: 5 | F32: 195 | G32: =F32*E32 -> 975
B33: REF - N002 | C33: FILTRE A HUILE | E33: 1 | F33: 291 | G33: =F33*E33 -> 291
B34: REF - N003 | C34: FILTRE A AIR | E34: 1 | F34: 511 | G34: =F34*E34 -> 511
B35: REF - N004 | C35: FILTRE A GASOIL | E35: 1 | F35: 803 | G35: =F35*E35 -> 803
B38: Montant Total article HT | G38: =SUM(G32:G37) -> 2580
B39: Main d'œuvre* | G39: 300
B40: Montant Total article HT (1) | G40: =+G38+G39 -> 2880
B41: TVA 20% (2) | G41: =+G40*I41 -> 576 | I41: 0.2
B42: Montant Total TTC (1+2) (3) | G42: =+G40+G41 -> 3456
B43: Commission SNTL (1x10%) (4) | G43: =G40*I43 -> 288 | I43: 0.1
B44: TVA 20% sur la comission (4x20%) (5) | E44: Cachet et Signature | G44: =G43*I44 -> 57.6 | I44: 0.2
B45: Montant Net à régler (3-4-5) | G45: =G42-G43-G44 -> 3110.4
B47: Arrêté la présente facture à la somme de Trois mille cent dix dirhams et quarante centimes TTC
E50: Cachet et signature
B55: * Non valable pour les bons ateliers ''A"

Sheet Annexe 25
A1: MONSTER GARAGE
D11: Facture N° | E11: 2026086 | F11: Date facture: | G11: 46140
D13: A
C15: La Société Nationale des Transports et de la Logistique (SNTL)
B18: Partenaire | D18: Véhicule | F18: Partenaire
B19: N° Agrément SNTL | C19: =+'Annexe 6 (1)'!C19 -> 3108 | D19: Matricule | E19: 217690 - J | F19: N° Accord SNTL
B20: Raison Sociale | C20: =+'Annexe 6 (1)'!C20 -> WIDINE MOTORS SERVICES | D20: Marque et modèle | E20: RENAULT KANGOO
B21: Adresse | C21: =+'Annexe 6 (1)'!C21 -> N°534 BIS 2 Q.I Sidi Ghanem | D21: Kilométrage | E21: 190931
B22: Ville | C22: =+'Annexe 6 (1)'!C22 -> Marrakech | D22: Administration | E22: COMMUNE HARBIL
B23: RC | C23: =+'Annexe 6 (1)'!C23 -> 150241 | D23: N° de bon | E23: 260126000024
B24: Patente | C24: =+'Annexe 6 (1)'!C24 -> 64006750
B25: IF | C25: =+'Annexe 6 (1)'!C25 -> 65976431
B26: ICE | C26: =+'Annexe 6 (1)'!C26 -> 003524622000063
B27: N° RIB | C27: =+'Annexe 6 (1)'!C27 -> 007450000612500000095129
B31: Référence article | C31: Désignation Article | E31: Quantité | F31: PU HT | G31: Total HT
B32: REF - N001 | C32: BATTERIE L3 - VARTA | E32: 1 | F32: 1141.67 | G32: =F32*E32 -> 1141.67
B37: Montant Total article HT | G37: =SUM(G32:G36) -> 1141.67
B38: Main d'œuvre* | G38: 200
B39: Montant Total article HT (1) | G39: =+G37+G38 -> 1341.67
B40: TVA 20% (2) | G40: =+G39*I40 -> 268.334 | I40: 0.2
B41: Montant Total TTC (1+2) (3) | G41: =+G39+G40 -> 1610.004
B42: Commission SNTL (1x10%) (4) | G42: =G39*I42 -> 134.167 | I42: 0.1
B43: TVA 20% sur la comission (4x20%) (5) | E43: Cachet et Signature | G43: =G42*I43 -> 26.8334 | I43: 0.2
B44: Montant Net à régler (3-4-5) | G44: =G41-G42-G43 -> 1449.0036
B46: Arrêté la présente facture à la somme de Mille quatre cent quarante neuf dirhams TTC
E49: Cachet et signature
B54: * Non valable pour les bons ateliers ''A"

Sheet Annexe 26
A1: MONSTER GARAGE
D11: Facture N° | E11: 2026091 | F11: Date facture: | G11: 46141
D13: A
C15: La Société Nationale des Transports et de la Logistique (SNTL)
B18: Partenaire | D18: Véhicule | F18: Partenaire
B19: N° Agrément SNTL | C19: =+'Annexe 6 (1)'!C19 -> 3108 | D19: Matricule | E19: 0219569 - J | F19: N° Accord SNTL
B20: Raison Sociale | C20: =+'Annexe 6 (1)'!C20 -> WIDINE MOTORS SERVICES | D20: Marque et modèle | E20: MITSUBISHI PAJERO SP
B21: Adresse | C21: =+'Annexe 6 (1)'!C21 -> N°534 BIS 2 Q.I Sidi Ghanem | D21: Kilométrage | E21: 210500
B22: Ville | C22: =+'Annexe 6 (1)'!C22 -> Marrakech | D22: Administration | E22: COMMUNE HARBIL
B23: RC | C23: =+'Annexe 6 (1)'!C23 -> 150241 | D23: N° de bon | E23: 260429000035
B24: Patente | C24: =+'Annexe 6 (1)'!C24 -> 64006750
B25: IF | C25: =+'Annexe 6 (1)'!C25 -> 65976431
B26: ICE | C26: =+'Annexe 6 (1)'!C26 -> 003524622000063
B27: N° RIB | C27: =+'Annexe 6 (1)'!C27 -> 007450000612500000095129
B31: Référence article | C31: Désignation Article | E31: Quantité | F31: PU HT | G31: Total HT
B32: REF - N001 | C32: AMPOULES LED | E32: 2 | F32: 800 | G32: =F32*E32 -> 1600
B37: Montant Total article HT | G37: =SUM(G32:G36) -> 1600
B38: Main d'œuvre* | G38: 200
B39: Montant Total article HT (1) | G39: =+G37+G38 -> 1800
B40: TVA 20% (2) | G40: =+G39*I40 -> 360 | I40: 0.2
B41: Montant Total TTC (1+2) (3) | G41: =+G39+G40 -> 2160
B42: Commission SNTL (1x10%) (4) | G42: =G39*I42 -> 180 | I42: 0.1
B43: TVA 20% sur la comission (4x20%) (5) | E43: Cachet et Signature | G43: =G42*I43 -> 36 | I43: 0.2
B44: Montant Net à régler (3-4-5) | G44: =G41-G42-G43 -> 1944
B46: Arrêté la présente facture à la somme de Mille neuf cent quarante quatre dirhams TTC
E49: Cachet et signature
B54: * Non valable pour les bons ateliers ''A"

Sheet Annexe  27
A1: MONSTER GARAGE
D11: Facture N° | E11: 2026092 | F11: Date facture: | G11: 46141
D13: A
C15: La Société Nationale des Transports et de la Logistique (SNTL)
B18: Partenaire | D18: Véhicule | F18: Partenaire
B19: N° Agrément SNTL | C19: =+'Annexe 6 (1)'!C19 -> 3108 | D19: Matricule | E19: 0248320 - J | F19: N° Accord SNTL
B20: Raison Sociale | C20: =+'Annexe 6 (1)'!C20 -> WIDINE MOTORS SERVICES | D20: Marque et modèle | E20: RENAULT MASTER
B21: Adresse | C21: =+'Annexe 6 (1)'!C21 -> N°534 BIS 2 Q.I Sidi Ghanem | D21: Kilométrage | E21: 100198
B22: Ville | C22: =+'Annexe 6 (1)'!C22 -> Marrakech | D22: Administration | E22: COMMUNE HARBIL
B23: RC | C23: =+'Annexe 6 (1)'!C23 -> 150241 | D23: N° de bon | E23: 260426000046
B24: Patente | C24: =+'Annexe 6 (1)'!C24 -> 64006750
B25: IF | C25: =+'Annexe 6 (1)'!C25 -> 65976431
B26: ICE | C26: =+'Annexe 6 (1)'!C26 -> 003524622000063
B27: N° RIB | C27: =+'Annexe 6 (1)'!C27 -> 007450000612500000095129
B31: Référence article | C31: Désignation Article | E31: Quantité | F31: PU HT | G31: Total HT
B32: REF - N001 | C32: HUILE MOTEUR | E32: 9 | F32: 180 | G32: =F32*E32 -> 1620
B33: REF - N002 | C33: FILTRE A AIR | E33: 1 | F33: 591.42 | G33: =F33*E33 -> 591.42
B34: REF - N003 | C34: FILTRE A GASOIL | E34: 1 | F34: 525.69 | G34: =F34*E34 -> 525.69
B35: REF - N004 | C35: FILTRE A HUILE | E35: 1 | F35: 259.2 | G35: =F35*E35 -> 259.2
B38: Montant Total article HT | G38: =SUM(G32:G37) -> 2996.31
B39: Main d'œuvre* | G39: 300.36
B40: Montant Total article HT (1) | G40: =+G38+G39 -> 3296.67
B41: TVA 20% (2) | G41: =+G40*I41 -> 659.334 | I41: 0.2
B42: Montant Total TTC (1+2) (3) | G42: =+G40+G41 -> 3956.004
B43: Commission SNTL (1x10%) (4) | G43: =G40*I43 -> 329.667 | I43: 0.1
B44: TVA 20% sur la comission (4x20%) (5) | E44: Cachet et Signature | G44: =G43*I44 -> 65.9334 | I44: 0.2
B45: Montant Net à régler (3-4-5) | G45: =G42-G43-G44 -> 3560.4036
B47: Arrêté la présente facture à la somme de Trois mille cinq cent soixante dirhams et quarante centimes TTC
E50: Cachet et signature
B55: * Non valable pour les bons ateliers ''A"

Sheet Annexe 28
A1: MONSTER GARAGE
D11: Facture N° | E11: 2026095 | F11: Date facture: | G11: 46141
D13: A
C15: La Société Nationale des Transports et de la Logistique (SNTL)
B18: Partenaire | D18: Véhicule | F18: Partenaire
B19: N° Agrément SNTL | C19: =+'Annexe 6 (1)'!C19 -> 3108 | D19: Matricule | E19: 0185418 - J | F19: N° Accord SNTL
B20: Raison Sociale | C20: =+'Annexe 6 (1)'!C20 -> WIDINE MOTORS SERVICES | D20: Marque et modèle | E20: DACIA DUSTER
B21: Adresse | C21: =+'Annexe 6 (1)'!C21 -> N°534 BIS 2 Q.I Sidi Ghanem | D21: Kilométrage | E21: 360500
B22: Ville | C22: =+'Annexe 6 (1)'!C22 -> Marrakech | D22: Administration | E22: COMMUNE HARBIL
B23: RC | C23: =+'Annexe 6 (1)'!C23 -> 150241 | D23: N° de bon | E23: 260429000062
B24: Patente | C24: =+'Annexe 6 (1)'!C24 -> 64006750
B25: IF | C25: =+'Annexe 6 (1)'!C25 -> 65976431
B26: ICE | C26: =+'Annexe 6 (1)'!C26 -> 003524622000063
B27: N° RIB | C27: =+'Annexe 6 (1)'!C27 -> 007450000612500000095129
B31: Référence article | C31: Désignation Article | E31: Quantité | F31: PU HT | G31: Total HT
B32: REF - N001 | C32: HUILE MOTEUR | E32: 5 | F32: 180 | G32: =F32*E32 -> 900
B33: REF - N002 | C33: FILTRE A HUILE | E33: 1 | F33: 232 | G33: =F33*E33 -> 232
B34: REF - N003 | C34: FILTRE A GASOIL | E34: 1 | F34: 522 | G34: =F34*E34 -> 522
B35: REF - N004 | C35: FILTRE A AIR | E35: 1 | F35: 422 | G35: =F35*E35 -> 422
B36: REF - N005 | C36: KIT EMBRAYAGE | E36: 1 | F36: 3300 | G36: =F36*E36 -> 3300
B37: REF - N006 | C37: AMOURTISSEURS AVANT | E37: 2 | F37: 980 | G37: =F37*E37 -> 1960
B39: Montant Total article HT | G39: =SUM(G32:G38) -> 7336
B40: Main d'œuvre* | G40: 950
B41: Montant Total article HT (1) | G41: =+G39+G40 -> 8286
B42: TVA 20% (2) | G42: =+G41*I42 -> 1657.2 | I42: 0.2
B43: Montant Total TTC (1+2) (3) | G43: =+G41+G42 -> 9943.2
B44: Commission SNTL (1x10%) (4) | G44: =G41*I44 -> 828.6 | I44: 0.1
B45: TVA 20% sur la comission (4x20%) (5) | E45: Cachet et Signature | G45: =G44*I45 -> 165.72 | I45: 0.2
B46: Montant Net à régler (3-4-5) | G46: =G43-G44-G45 -> 8948.88
B48: Arrêté la présente facture à la somme de Huit mille neuf cent quarante huit dirhams et quatre vingt huit centimes TTC
E51: Cachet et signature
B56: * Non valable pour les bons ateliers ''A"

Sheet Annexe 29
A1: MONSTER GARAGE
D11: Facture N° | E11: 20260101 | F11: Date facture: | G11: 46141
D13: A
C15: La Société Nationale des Transports et de la Logistique (SNTL)
B18: Partenaire | D18: Véhicule | F18: Partenaire
B19: N° Agrément SNTL | C19: =+'Annexe 6 (1)'!C19 -> 3108 | D19: Matricule | E19: 0207789 - J | F19: N° Accord SNTL
B20: Raison Sociale | C20: =+'Annexe 6 (1)'!C20 -> WIDINE MOTORS SERVICES | D20: Marque et modèle | E20: FORD TRANSIT
B21: Adresse | C21: =+'Annexe 6 (1)'!C21 -> N°534 BIS 2 Q.I Sidi Ghanem | D21: Kilométrage | E21: 342632
B22: Ville | C22: =+'Annexe 6 (1)'!C22 -> Marrakech | D22: Administration | E22: COMMUNE HARBIL
B23: RC | C23: =+'Annexe 6 (1)'!C23 -> 150241 | D23: N° de bon | E23: 260429000031
B24: Patente | C24: =+'Annexe 6 (1)'!C24 -> 64006750
B25: IF | C25: =+'Annexe 6 (1)'!C25 -> 65976431
B26: ICE | C26: =+'Annexe 6 (1)'!C26 -> 003524622000063
B27: N° RIB | C27: =+'Annexe 6 (1)'!C27 -> 007450000612500000095129
B31: Référence article | C31: Désignation Article | E31: Quantité | F31: PU HT | G31: Total HT
B32: REF - N001 | C32: BOITIER GEO-LOCALISATION GPS | E32: 1 | F32: 6083.33 | G32: =F32*E32 -> 6083.33
B33: REF - N002 | C33: MODULE GASOIL | E33: 1 | F33: 600 | G33: =F33*E33 -> 600
B36: Montant Total article HT | G36: =SUM(G32:G35) -> 6683.33
B37: Main d'œuvre* | G37: 300
B38: Montant Total article HT (1) | G38: =+G36+G37 -> 6983.33
B39: TVA 20% (2) | G39: =+G38*I39 -> 1396.666 | I39: 0.2
B40: Montant Total TTC (1+2) (3) | G40: =+G38+G39 -> 8379.996
B41: Commission SNTL (1x10%) (4) | G41: =G38*I41 -> 698.333 | I41: 0.1
B42: TVA 20% sur la comission (4x20%) (5) | E42: Cachet et Signature | G42: =G41*I42 -> 139.6666 | I42: 0.2
B43: Montant Net à régler (3-4-5) | G43: =G40-G41-G42 -> 7541.9964
B45: Arrêté la présente facture à la somme de Sept mille cinq cent quarante deux dirhams TTC
E48: Cachet et signature
B53: * Non valable pour les bons ateliers ''A"

Sheet Annexe 30
A1: MONSTER GARAGE
D11: Facture N° | E11: 20260102 | F11: Date facture: | G11: 46141
D13: A
C15: La Société Nationale des Transports et de la Logistique (SNTL)
B18: Partenaire | D18: Véhicule | F18: Partenaire
B19: N° Agrément SNTL | C19: =+'Annexe 6 (1)'!C19 -> 3108 | D19: Matricule | E19: 0248319- J | F19: N° Accord SNTL
B20: Raison Sociale | C20: =+'Annexe 6 (1)'!C20 -> WIDINE MOTORS SERVICES | D20: Marque et modèle | E20: FIAT DOBLO CR
B21: Adresse | C21: =+'Annexe 6 (1)'!C21 -> N°534 BIS 2 Q.I Sidi Ghanem | D21: Kilométrage | E21: 59774
B22: Ville | C22: =+'Annexe 6 (1)'!C22 -> Marrakech | D22: Administration | E22: COMMUNE HARBIL
B23: RC | C23: =+'Annexe 6 (1)'!C23 -> 150241 | D23: N° de bon | E23: 260429000068
B24: Patente | C24: =+'Annexe 6 (1)'!C24 -> 64006750
B25: IF | C25: =+'Annexe 6 (1)'!C25 -> 65976431
B26: ICE | C26: =+'Annexe 6 (1)'!C26 -> 003524622000063
B27: N° RIB | C27: =+'Annexe 6 (1)'!C27 -> 007450000612500000095129
B31: Référence article | C31: Désignation Article | E31: Quantité | F31: PU HT | G31: Total HT
B32: REF - N001 | C32: BOITIER GEO-LOCALISATION GPS | E32: 1 | F32: 6083.33 | G32: =F32*E32 -> 6083.33
B33: REF - N002 | C33: MODULE GASOIL | E33: 1 | F33: 600 | G33: =F33*E33 -> 600
B36: Montant Total article HT | G36: =SUM(G32:G35) -> 6683.33
B37: Main d'œuvre* | G37: 300
B38: Montant Total article HT (1) | G38: =+G36+G37 -> 6983.33
B39: TVA 20% (2) | G39: =+G38*I39 -> 1396.666 | I39: 0.2
B40: Montant Total TTC (1+2) (3) | G40: =+G38+G39 -> 8379.996
B41: Commission SNTL (1x10%) (4) | G41: =G38*I41 -> 698.333 | I41: 0.1
B42: TVA 20% sur la comission (4x20%) (5) | E42: Cachet et Signature | G42: =G41*I42 -> 139.6666 | I42: 0.2
B43: Montant Net à régler (3-4-5) | G43: =G40-G41-G42 -> 7541.9964
B45: Arrêté la présente facture à la somme de Sept mille cinq cent quarante deux dirhams TTC
E48: Cachet et signature
B53: * Non valable pour les bons ateliers ''A"

Sheet Annexe 31
A1: MONSTER GARAGE
D11: Facture N° | E11: 20260103 | F11: Date facture: | G11: 46141
D13: A
C15: La Société Nationale des Transports et de la Logistique (SNTL)
B18: Partenaire | D18: Véhicule | F18: Partenaire
B19: N° Agrément SNTL | C19: =+'Annexe 6 (1)'!C19 -> 3108 | D19: Matricule | E19: 0257528 - J | F19: N° Accord SNTL
B20: Raison Sociale | C20: =+'Annexe 6 (1)'!C20 -> WIDINE MOTORS SERVICES | D20: Marque et modèle | E20: RENAULT MASTER
B21: Adresse | C21: =+'Annexe 6 (1)'!C21 -> N°534 BIS 2 Q.I Sidi Ghanem | D21: Kilométrage | E21: 57190
B22: Ville | C22: =+'Annexe 6 (1)'!C22 -> Marrakech | D22: Administration | E22: COMMUNE HARBIL
B23: RC | C23: =+'Annexe 6 (1)'!C23 -> 150241 | D23: N° de bon | E23: 260429000039
B24: Patente | C24: =+'Annexe 6 (1)'!C24 -> 64006750
B25: IF | C25: =+'Annexe 6 (1)'!C25 -> 65976431
B26: ICE | C26: =+'Annexe 6 (1)'!C26 -> 003524622000063
B27: N° RIB | C27: =+'Annexe 6 (1)'!C27 -> 007450000612500000095129
B31: Référence article | C31: Désignation Article | E31: Quantité | F31: PU HT | G31: Total HT
B32: REF - N001 | C32: BOITIER GEO LOCALISATION GPS | E32: 1 | F32: 6083.33 | G32: =F32*E32 -> 6083.33
B33: REF - N002 | C33: MODULE GASOIL | E33: 1 | F33: 600 | G33: =F33*E33 -> 600
B36: Montant Total article HT | G36: =SUM(G32:G35) -> 6683.33
B37: Main d'œuvre* | G37: 300
B38: Montant Total article HT (1) | G38: =+G36+G37 -> 6983.33
B39: TVA 20% (2) | G39: =+G38*I39 -> 1396.666 | I39: 0.2
B40: Montant Total TTC (1+2) (3) | G40: =+G38+G39 -> 8379.996
B41: Commission SNTL (1x10%) (4) | G41: =G38*I41 -> 698.333 | I41: 0.1
B42: TVA 20% sur la comission (4x20%) (5) | E42: Cachet et Signature | G42: =G41*I42 -> 139.6666 | I42: 0.2
B43: Montant Net à régler (3-4-5) | G43: =G40-G41-G42 -> 7541.9964
B45: Arrêté la présente facture à la somme de Sept mille cinq cent quarante deux dirhams TTC
E48: Cachet et signature
B53: * Non valable pour les bons ateliers ''A"

Sheet Annexe 32
A1: MONSTER GARAGE
D11: Facture N° | E11: 20260105 | F11: Date facture: | G11: 46141
D13: A
C15: La Société Nationale des Transports et de la Logistique (SNTL)
B18: Partenaire | D18: Véhicule | F18: Partenaire
B19: N° Agrément SNTL | C19: =+'Annexe 6 (1)'!C19 -> 3108 | D19: Matricule | E19: 0248320 - J | F19: N° Accord SNTL
B20: Raison Sociale | C20: =+'Annexe 6 (1)'!C20 -> WIDINE MOTORS SERVICES | D20: Marque et modèle | E20: RENAULT MASTER
