Workbook

Sheet JOURNAL DE CAISSE
A1: MONSTER GARAGE
O4: TABLEAU DE SUIVI :
A5: JOURNAL DE CAISSE | B5: WIDINE MOTORS SERVICE
L6: N° de pièce | N6: Date | P6: Désignation | R6: Entrée | T6: Sortie
A7: PERIODE DU | B7: 46113 | C7: AU | D7: 46142 | L7: GARAGE | N7: 46115 | P7: Papier peint | T7: 1200
L8: GARAGE | N8: 46116 | P8: dépannage | T8: 250
L9: GARAGE | N9: 46120 | O9: Electricité | T9: =4000+950+450 -> 5400
A10: N° de pièce | B10: Date | C10: Désignation | D10: Entrée | E10: Sortie | L10: GARAGE | N10: 46121 | O10: ELECTRICIEN | T10: 300
A11: GARAGE | B11: 46113 | C11: Tide | E11: 18 | L11: GARAGE | N11: 46132 | O11: garage | T11: 1000
A12: GARAGE | B12: 46113 | C12: Déjeuner | E12: 200 | L12: GARAGE | N12: 46135 | O12: Said déjeuner | T12: 500
A13: GARAGE | B13: 46113 | C13: Parfum | E13: 15
A14: GARAGE | B14: 46114 | C14: COMPRESSEUR CLIM | E14: 200
A15: GARAGE | B15: 46114 | C15: Eau | E15: 50 | R15: Total | T15: =SUM(T7:U13) -> 8650
A16: GARAGE | B16: 46114 | C16: Ménage | E16: 100
A17: GARAGE | B17: 46115 | C17: VERNIS / BUREAU | E17: 69
A18: GARAGE | B18: 46116 | C18: BOUTEILLE DE GAZ | E18: 55.5 | J18: TABLEAU DES TRAVAUX DES VEHICULES
A19: GARAGE | B19: 46118 | C19: Produit ntt | E19: 20
A20: GARAGE | B20: 46118 | C20: FEUILLES DE PAPIER | E20: 50
A21: GARAGE | B21: 46119 | C21: Garage | E21: 25 | I21: Date | K21: Véhicule | L21: Immatriculation | N21: Travail effectué | S21: Mécanicient
A22: GARAGE | B22: 46119 | C22: Cable | E22: 20 | I22: 46115 | K22: Mercedes G63 | N22: Vidange simple | S22: youssef
A23: GARAGE | B23: 46119 | C23: Grafeuse | E23: 30 | I23: 46115 | K23: BMW | N23: Vidange complet | S23: youssef
A24: GARAGE | B24: 46120 | C24: Déjaeuner | E24: 50 | I24: 46112 | K24: Hyundai creta | S24: yassine
A25: GARAGE | B25: 46120 | C25: Cable | E25: 203 | I25: 46112 | K25: VW passat | N25: vidange simple | S25: yassine
A26: GARAGE | B26: 46120 | C26: Souris | E26: 80 | I26: 46113 | K26: pajero | N26: kit-VC | S26: yassine
A27: GARAGE | B27: 46120 | C27: Tide | E27: 16 | I27: 46116 | K27: VW T | S27: yassine
A28: GARAGE | B28: 46120 | C28: Ahmed | E28: 100 | I28: 46116 | K28: Peugeot | N28: Pompe embrayage | S28: yassine
A29: GARAGE | B29: 46120 | C29: Electricien | E29: 200 | I29: 46119 | K29: ford tr HAR | N29: vidange simple | S29: yassine
A30: GARAGE | B30: 46121 | C30: Ménage | E30: 200 | I30: 46119 | K30: Toyota narsa | N30: VC plaquette | S30: yassine
A31: GARAGE | B31: 46121 | C31: VW | E31: 33 | I31: 46120 | K31: Hyundai I40 | N31: VC | S31: yassine
A32: GARAGE | B32: 46122 | C32: Cable | E32: 50 | I32: 46122 | K32: DACIA DUSTER WILA | L32: M218563 | N32: AMRT+PLAQUETTE+VS+KIT+TENDEUR+ | S32: yassine
A33: GARAGE | B33: 46122 | C33: Déjauner | E33: 120 | I33: 46127 | K33: RENAULT | N33: RADIATEUR D HUILE | S33: YASSINE
A34: GARAGE | B34: 46122 | C34: Garage | E34: 10 | I34: 46128 | K34: RENAULT MASTER | L34: 248320 - J | N34: VC -COURROIE | S34: YASSINE
A35: GARAGE | B35: 46123 | C35: Déjeuner | E35: 100 | I35: 46130 | K35: PGT BOXER | L35: M234914 | N35: REF+VS | S35: YASSINE
A36: GARAGE | B36: 46127 | C36: Dépannage | E36: 200 | I36: 46132 | K36: DACIA LOGAN | L36: 91092-A-26 | N36: AMRT | S36: YASSINE
A37: GARAGE | B37: 46127 | C37: Said produit | E37: 100 | I37: 46133 | K37: AUDI | N37: PLAQUETTES | S37: YASSINE
A38: GARAGE | B38: 46127 | C38: Oni | E38: 16 | I38: 46135 | K38: PEUGEOT PARTNER | L38: M174633 | S38: YASSINE
A39: GARAGE | B39: 46127 | C39: Salaire abdeslam | E39: 50 | I39: 46136 | K39: DACIA DUSTER WILA | L39: M218563
A40: GARAGE | B40: 46128 | C40: Ménage | E40: 200 | I40: 46136 | K40: DACIA DUSTER HARBIL | L40: J185418 | N40: VS+INJECTEUFR
A41: GARAGE | B41: 46128 | C41: Dépannage | E41: 300 | I41: 46140 | K41: MITSUBISHI PAJERO SPORT HARB | N41: amortisseurs
A42: GARAGE | B42: 46129 | C42: rincage yassine | E42: 200
...

Sheet SALAIRES
A1: MONSTER GARAGE
A5: LIVRE DE CAISSE OUVRIERS A LA TACHE | D5: WIDINE MOTORS SERVICE
B7: PERIODE DU | C7: =+'JOURNAL DE CAISSE'!B7 -> 46113 | D7: AU | E7: =+'JOURNAL DE CAISSE'!D7 -> 46142
H9: 100
A10: Nom & Prénom | B10: Date | C10: Montant | D10: Fonction | E10: Observations
A11: SAID | B11: 46113 | C11: 300 | D11: SAID | E11: AVANCE
A12: ABDELALI | B12: 46113 | C12: 500 | D12: TACHE | E12: MERCEDES
A13: AZIZ | B13: 46116 | C13: 700 | D13: ELECTRICIEN
A14: TARIK | B14: 46120 | C14: 300 | D14: DIAGNOSTIC
A15: YASSINE | D15: MECANICIEN
A16: FENNI | B16: 46113 | C16: 800 | D16: ADMINIST | E16: CUMUL
A17: FENNI | B17: 46113 | C17: 300 | D17: ADMINIST | E17: DEJEUNER/AMINE
A18: SIMOHAMED | B18: 46116 | C18: 2000 | D18: PEINTRE | E18: CREDIT
A19: SAID | B19: 46118 | C19: =600+300 -> 900 | D19: SAID | E19: PRIME
A20: SAID | B20: 46118 | C20: 400 | D20: SAID | E20: PRIME
A21: SIMOHAMED | B21: 46118 | C21: 200 | D21: PEINTRE | E21: PRIME
A22: SAID | B22: 46121 | C22: 100 | D22: SAID | E22: PRIME
A23: FENNI | B23: 46121 | C23: 200 | D23: ADMINIST | E23: AVANCE
A24: SAID | B24: 46122 | C24: 1000 | D24: SAID | E24: AVANCE
A25: TARIK | B25: 46123 | C25: 100 | D25: DIAGNOSTIC
A26: AZIZ | B26: 46123 | C26: 200 | D26: ELECTRICIEN
A27: AYOUB | B27: 46122 | C27: 3000 | D27: TACHE | E27: MECANICIEN NAUTIQUE - RESTE = 4000DH
A28: SIMOHAMED | B28: 46127 | C28: =3200-500 -> 2700 | D28: PEINTRE | E28: QUINZ 15/04/2026
A29: SAID | B29: 46127 | C29: =5000-1000-300 -> 3700 | D29: SAID | E29: QUINZ 15/04/2026
A30: ABDESLAM | B30: 46127 | C30: 2250 | D30: TOLIER | E30: QUINZ 15/04/2026
A31: ZOUHEIR | B31: 46127 | C31: 1600 | D31: OUVRIER | E31: QUINZ 15/04/2026
A32: OUTHMANE | B32: 46127 | C32: 1600 | D32: PEINTRE | E32: QUINZ 15/04/2026
A33: SALIMA | B33: 46127 | C33: 1500 | D33: ADMINIST | E33: QUINZ 15/04/2026
A34: FENNI | B34: 46127 | C34: =1200 -> 1200 | D34: ADMINIST | E34: QUINZ 15/04/2026
A35: 46128 | C35: Total : | D35: =SUM(C11:C34) -> 25550
A37: AZIZ | B37: 46128 | C37: 400 | D37: ELECTRICIEN
A38: SAID | B38: 46129 | C38: 200 | D38: SAID | E38: AVANCE
A39: SAID | B39: 46130 | C39: 200 | D39: SAID | E39: PRIME
A40: TARIK | B40: 46130 | C40: 500 | D40: DIAGNOSTIC
A41: YASSINE | B41: 46130 | C41: 1000 | D41: MECANICIEN | E41: AVANCE
A42: AZIZ | B42: 46130 | C42: 400 | D42: ELECTRICIEN
A43: SAID | B43: 46134 | C43: 200 | D43: SAID | E43: AVANCE
A44: SIMOHAMED | B44: 46135 | C44: 200 | D44: PEINTRE | E44: AVANCE
A45: OUTHMANE | B45: 46135 | C45: 200 | D45: PEINTRE | E45: AVANCE
A46: ABDESLAM | B46: 46136 | C46: 600 | D46: TOLIER | E46: AVANCE
...

Sheet DETAIL CA MOIS
B1: MONSTER GARAGE
B5: DETAIL CA MENSUEL | D5: WIDINE MOTORS SERVICE
B7: PERIODE DU | C7: =+SALAIRES!C7 -> 46113 | D7: AU | E7: =+SALAIRES!E7 -> 46142
G8: 1
A12: N. CLT & NUMERO | B12: VEHICULE | C12: IMMATRICULATION | D12: MONTANT FACTURE | E12: ENCAISSE | F12: A ENCAISSER | G12: N° TEL | H12: KM
A13: - | B13: PGT 308 | C13: FR DS-211-MA | D13: 2700 | E13: 2700 | F13: =+D13-E13 -> 0
A14: - | B14: MERCEDES G63 AMG | C14: 26826 - T - 1 | D14: 2000 | E14: 2000 | F14: =+D14-E14 -> 0
A15: 100-83 | B15: DACIA LOGAN - WILA | C15: M 195033 | D15: 8182 | F15: =+D15-E15 -> 8182
A16: 300-84 | B16: TOYOTA HILUX - NARSA | C16: M 215843 | D16: 4068 | F16: =+D16-E16 -> 4068
A17: 600 - 85 | B17: HYUNDAI I40 | C17: J 202955 | D17: 3456 | F17: =+D17-E17 -> 3456
A18: 600 - 86 | B18: RENAULT KANGOO - HARB | C18: J 217690 | D18: 1610 | F18: =+D18-E18 -> 1610
A19: 100 - 87 | B19: DACIA DUSTER - WILA | C19: M218563 | D19: 9877.2 | F19: =+D19-E19 -> 9877.2
A20: 100-88 | B20: DACIA DUSTER - WILA | C20: M218563 | D20: 9688.8 | F20: =+D20-E20 -> 9688.8
A21: - | B21: HYUNDAI TUCSON | C21: 60915 - T - 6 | F21: =+D21-E21 -> 0
A22: 800 - 89 | B22: DACIA LOGAN-AMEE | C22: M216483 | D22: 1920 | F22: =+D22-E22 -> 1920
A23: 100 -90 | B23: DACIA DUSTER - WILA | C23: M235133 | D23: 1200 | F23: =+D23-E23 -> 1200
A24: 300 - … | B24: DACIA DOCKER - NARSA | C24: M197496 | D24: 1536 | F24: =+D24-E24 -> 1536 | G24: X
A25: 600-91 | B25: MITSUBISHI PAJERO SPORT HARB | C25: J 219569 | D25: 2160 | F25: =+D25-E25 -> 2160
A26: - | B26: RLT CAPTUR | C26: 14018 - D - 26 | D26: 1000 | E26: 1000 | F26: =+D26-E26 -> 0
A27: - | B27: HYUNDAI TUCSON | C27: WW713814 | F27: =+D27-E27 -> 0
A28: 600-92 | B28: RENAULT MASTER HARB | C28: J 248320 | D28: 3956 | F28: =+D28-E28 -> 3956
A29: 100-93 | B29: MERCEDES E350d | C29: 116-96 | D29: 900 | F29: =+D29-E29 -> 900
A30: 100 - 94 | B30: DACIA DUSTER WILA | C30: M199903 | D30: 9960 | H30: KM 186732
A31: 600 - 95 | B31: DACIA DUSTER HARBIL | C31: J 185418 | D31: 9943.2 | F31: =+D31-E31 -> 9943.2
A32: - | B32: DACIA LOGAN | C32: 91092-A-26 | D32: 6000 | E32: 6000 | F32: =+D32-E32 -> 0
A33: 100 - 96 | B33: PGT BOXER | C33: M234914 | D33: 6633 | F33: =+D33-E33 -> 6633
A34: - | B34: PORSCHE 911 | C34: ESPAGNE | D34: 1000 | E34: 1000 | F34: =+D34-E34 -> 0
A35: 100 - 97 | B35: DACIA DUSTER - WILA | C35: M218563 | D35: 7200 | F35: =+D35-E35 -> 7200
A36: 100 - 98 | B36: JEEP GD CHEROKEE | C36: 41724 - T - 1 | D36: 1968 | F36: =+D36-E36 -> 1968
A37: 300-… | B37: PEUGEOT PARTNER | C37: M174633 | D37: 4325 | F37: =+D37-E37 -> 4325 | H37: KM 211263
A38: 600-100 | B38: DACIA LOGAN HARBIL | C38: J204318 | D38: 9962 | F38: =+D38-E38 -> 9962 | H38: KM 246235
A39: 600-101 | B39: FORD TRANSIT HARBIL | C39: J207789 | D39: 8380 | F39: =+D39-E39 -> 8380 | H39: KM342632
A40: 600-102 | B40: FIAT DOBLO HARBIL | C40: J0248319 | D40: 8380 | F40: =+D40-E40 -> 8380 | H40: KM59774
A41: 600-103 | B41: RENAULT MASTER HARB | C41: J0257528 | D41: 8380 | F41: =+D41-E41 -> 8380 | H41: KM57190
A42: - | B42: CLIO | C42: 55449-D-26 | F42: =+D42-E42 -> 0
A43: 800-104 | B43: VW PASSAT | C43: M166303 | D43: 1896 | F43: =+D43-E43 -> 1896 | H43: 471884
A44: 600-105 | B44: RENAULT MASTER HARB | C44: J0248320 | D44: 8380 | F44: =+D44-E44 -> 8380 | H44: 100980
A45: 600-99 | B45: MITSUBISHI PAJERO SPORT HARB | C45: J219569 | D45: 8380 | F45: =+D45-E45 -> 8380 | H45: 210831
A46: 010-106 | B46: MERCEDES | C46: 76786-B-26 | F46: =+D46-E46 -> 0
A47: 600-107 | B47: RENAULT MASTER HARB | C47: J0248320 | D47: 3747 | F47: =+D47-E47 -> 3747 | H47: KM101074
...

Sheet BCE
C1: MONSTER GARAGE
B5: PERIODE DU | D5: =+'DETAIL CA MOIS'!C7 -> 46113 | F5: =+'DETAIL CA MOIS'!D7 -> AU | I5: =+'DETAIL CA MOIS'!E7 -> 46142
A9: VEHICULE | B9: IMMATRICULATION | C9: MONTANT FACTURE | D9: ENCAISSE | E9: A ENCAISSER | F9: C DE REVIENT | G9: BCE PREV | H9: BCE TOTAL ACTUEL | I9: AMORT CH FIXES | J9: BCE ACTUEL - CH FIXES | K9: BCE PREV - CH FIXES
A10: =+'DETAIL CA MOIS'!B13 -> PGT 308 | B10: =+'DETAIL CA MOIS'!C13 -> FR DS-211-MA | C10: =+'DETAIL CA MOIS'!D13 -> 2700 | D10: =+'DETAIL CA MOIS'!E13 -> 2700 | E10: =+'DETAIL CA MOIS'!F13 -> 0 | F10: =751.1+30 -> 781.1 | G10: =C10-F10 -> 1918.9 | H10: =+D10-F10 -> 1918.9 | I10: =70000/29 -> 2413.7931 | J10: =+H10-I10 -> -494.8931 | K10: =+G10-I10 -> -494.8931
A11: =+'DETAIL CA MOIS'!B14 -> MERCEDES G63 AMG | B11: =+'DETAIL CA MOIS'!C14 -> 26826 - T - 1 | C11: =+'DETAIL CA MOIS'!D14 -> 2000 | D11: =+'DETAIL CA MOIS'!E14 -> 2000 | E11: =+'DETAIL CA MOIS'!F14 -> 0 | F11: =100+600+300+15 -> 1015 | G11: =C11-F11 -> 985 | H11: =+D11-F11 -> 985 | I11: =70000/29 -> 2413.7931 | J11: =+H11-I11 -> -1428.7931 | K11: =+G11-I11 -> -1428.7931
A12: =+'DETAIL CA MOIS'!B15 -> DACIA LOGAN - WILA | B12: =+'DETAIL CA MOIS'!C15 -> M 195033 | C12: =+'DETAIL CA MOIS'!D15 -> 8182 | D12: =+'DETAIL CA MOIS'!E15 -> 0 | E12: =+'DETAIL CA MOIS'!F15 -> 8182 | F12: =+C12*0.35+70+890+190 -> 4013.7 | G12: =C12-F12 -> 4168.3 | H12: =+D12-F12 -> -4013.7 | I12: =70000/29 -> 2413.7931 | J12: =+H12-I12 -> -6427.4931 | K12: =+G12-I12 -> 1754.5069
A13: =+'DETAIL CA MOIS'!B16 -> TOYOTA HILUX - NARSA | B13: =+'DETAIL CA MOIS'!C16 -> M 215843 | C13: =+'DETAIL CA MOIS'!D16 -> 4068 | D13: =+'DETAIL CA MOIS'!E16 -> 0 | E13: =+'DETAIL CA MOIS'!F16 -> 4068 | F13: =+C13*0.15+653 -> 1263.2 | G13: =C13-F13 -> 2804.8 | H13: =+D13-F13 -> -1263.2 | I13: =70000/29 -> 2413.7931 | J13: =+H13-I13 -> -3676.9931 | K13: =+G13-I13 -> 391.0069
A14: =+'DETAIL CA MOIS'!B17 -> HYUNDAI I40 | B14: =+'DETAIL CA MOIS'!C17 -> J 202955 | C14: =+'DETAIL CA MOIS'!D17 -> 3456 | D14: =+'DETAIL CA MOIS'!E17 -> 0 | E14: =+'DETAIL CA MOIS'!F17 -> 3456 | F14: =+C14*0.15+780 -> 1298.4 | G14: =C14-F14 -> 2157.6 | H14: =+D14-F14 -> -1298.4 | I14: =70000/29 -> 2413.7931 | J14: =+H14-I14 -> -3712.1931 | K14: =+G14-I14 -> -256.1931
A15: =+'DETAIL CA MOIS'!B18 -> RENAULT KANGOO - HARB | B15: =+'DETAIL CA MOIS'!C18 -> J 217690 | C15: =+'DETAIL CA MOIS'!D18 -> 1610 | D15: =+'DETAIL CA MOIS'!E18 -> 0 | E15: =+'DETAIL CA MOIS'!F18 -> 1610 | F15: =+C15*0.15+930 -> 1171.5 | G15: =C15-F15 -> 438.5 | H15: =+D15-F15 -> -1171.5 | I15: =70000/29 -> 2413.7931 | J15: =+H15-I15 -> -3585.2931 | K15: =+G15-I15 -> -1975.2931
A16: =+'DETAIL CA MOIS'!B19 -> DACIA DUSTER - WILA | B16: =+'DETAIL CA MOIS'!C19 -> M218563 | C16: =+'DETAIL CA MOIS'!D19 -> 9877.2 | D16: =+'DETAIL CA MOIS'!E19 -> 0 | E16: =+'DETAIL CA MOIS'!F19 -> 9877.2 | F16: =+C16*0.15+6421.25 -> 7902.83 | G16: =C16-F16 -> 1974.37 | H16: =+D16-F16 -> -7902.83 | I16: =70000/29 -> 2413.7931 | J16: =+H16-I16 -> -10316.623 | K16: =+G16-I16 -> -439.4231
A17: =+'DETAIL CA MOIS'!B20 -> DACIA DUSTER - WILA | B17: =+'DETAIL CA MOIS'!C20 -> M218563 | C17: =+'DETAIL CA MOIS'!D20 -> 9688.8 | D17: =+'DETAIL CA MOIS'!E20 -> 0 | E17: =+'DETAIL CA MOIS'!F20 -> 9688.8 | F17: =+C17*0.15 -> 1453.32 | G17: =C17-F17 -> 8235.48 | H17: =+D17-F17 -> -1453.32 | I17: =70000/29 -> 2413.7931 | J17: =+H17-I17 -> -3867.1131 | K17: =+G17-I17 -> 5821.6869
A18: =+'DETAIL CA MOIS'!B21 -> HYUNDAI TUCSON | B18: =+'DETAIL CA MOIS'!C21 -> 60915 - T - 6 | C18: =+'DETAIL CA MOIS'!D21 -> 0 | D18: =+'DETAIL CA MOIS'!E21 -> 0 | E18: =+'DETAIL CA MOIS'!F21 -> 0 | F18: 200 | G18: =C18-F18 -> -200 | H18: =+D18-F18 -> -200 | I18: =70000/29 -> 2413.7931 | J18: =+H18-I18 -> -2613.7931 | K18: =+G18-I18 -> -2613.7931
A19: =+'DETAIL CA MOIS'!B22 -> DACIA LOGAN-AMEE | B19: =+'DETAIL CA MOIS'!C22 -> M216483 | C19: =+'DETAIL CA MOIS'!D22 -> 1920 | D19: =+'DETAIL CA MOIS'!E22 -> 0 | E19: =+'DETAIL CA MOIS'!F22 -> 1920 | F19: =+C19*0.15+680 -> 968 | G19: =C19-F19 -> 952 | H19: =+D19-F19 -> -968 | I19: =70000/29 -> 2413.7931 | J19: =+H19-I19 -> -3381.7931 | K19: =+G19-I19 -> -1461.7931
A20: =+'DETAIL CA MOIS'!B23 -> DACIA DUSTER - WILA | B20: =+'DETAIL CA MOIS'!C23 -> M235133 | C20: =+'DETAIL CA MOIS'!D23 -> 1200 | D20: =+'DETAIL CA MOIS'!E23 -> 0 | E20: =+'DETAIL CA MOIS'!F23 -> 1200 | F20: =+C20*0.15 -> 180 | G20: =C20-F20 -> 1020 | H20: =+D20-F20 -> -180 | I20: =70000/29 -> 2413.7931 | J20: =+H20-I20 -> -2593.7931 | K20: =+G20-I20 -> -1393.7931
A21: =+'DETAIL CA MOIS'!B24 -> DACIA DOCKER - NARSA | B21: =+'DETAIL CA MOIS'!C24 -> M197496 | C21: =+'DETAIL CA MOIS'!D24 -> 1536 | D21: =+'DETAIL CA MOIS'!E24 -> 0 | E21: =+'DETAIL CA MOIS'!F24 -> 1536 | F21: =+C21*0.15+680 -> 910.4 | G21: =C21-F21 -> 625.6 | H21: =+D21-F21 -> -910.4 | I21: =70000/29 -> 2413.7931 | J21: =+H21-I21 -> -3324.1931 | K21: =+G21-I21 -> -1788.1931
A22: =+'DETAIL CA MOIS'!B25 -> MITSUBISHI PAJERO SPORT HARB | B22: =+'DETAIL CA MOIS'!C25 -> J 219569 | C22: =+'DETAIL CA MOIS'!D25 -> 2160 | D22: =+'DETAIL CA MOIS'!E25 -> 0 | E22: =+'DETAIL CA MOIS'!F25 -> 2160 | F22: =+C22*0.15+20 -> 344 | G22: =C22-F22 -> 1816 | H22: =+D22-F22 -> -344 | I22: =70000/29 -> 2413.7931 | J22: =+H22-I22 -> -2757.7931 | K22: =+G22-I22 -> -597.7931
A23: =+'DETAIL CA MOIS'!B26 -> RLT CAPTUR | B23: =+'DETAIL CA MOIS'!C26 -> 14018 - D - 26 | C23: =+'DETAIL CA MOIS'!D26 -> 1000 | D23: =+'DETAIL CA MOIS'!E26 -> 1000 | E23: =+'DETAIL CA MOIS'!F26 -> 0 | F23: 100 | G23: =C23-F23 -> 900 | H23: =+D23-F23 -> 900 | I23: =70000/29 -> 2413.7931 | J23: =+H23-I23 -> -1513.7931 | K23: =+G23-I23 -> -1513.7931
A24: =+'DETAIL CA MOIS'!B27 -> HYUNDAI TUCSON | B24: =+'DETAIL CA MOIS'!C27 -> WW713814 | C24: =+'DETAIL CA MOIS'!D27 -> 0 | D24: =+'DETAIL CA MOIS'!E27 -> 0 | E24: =+'DETAIL CA MOIS'!F27 -> 0 | F24: =80+200 -> 280 | G24: =C24-F24 -> -280 | H24: =+D24-F24 -> -280 | I24: =70000/29 -> 2413.7931 | J24: =+H24-I24 -> -2693.7931 | K24: =+G24-I24 -> -2693.7931
A25: =+'DETAIL CA MOIS'!B28 -> RENAULT MASTER HARB | B25: =+'DETAIL CA MOIS'!C28 -> J 248320 | C25: =+'DETAIL CA MOIS'!D28 -> 3956 | D25: =+'DETAIL CA MOIS'!E28 -> 0 | E25: =+'DETAIL CA MOIS'!F28 -> 3956 | F25: =+C25*0.25+57*9+72+80+90 -> 1744 | G25: =C25-F25 -> 2212 | H25: =+D25-F25 -> -1744 | I25: =70000/29 -> 2413.7931 | J25: =+H25-I25 -> -4157.7931 | K25: =+G25-I25 -> -201.7931
A26: =+'DETAIL CA MOIS'!B29 -> MERCEDES E350d | B26: =+'DETAIL CA MOIS'!C29 -> 116-96 | C26: =+'DETAIL CA MOIS'!D29 -> 900 | D26: =+'DETAIL CA MOIS'!E29 -> 0 | E26: =+'DETAIL CA MOIS'!F29 -> 900 | F26: =+C26*0.15 -> 135 | G26: =C26-F26 -> 765 | H26: =+D26-F26 -> -135 | I26: =70000/29 -> 2413.7931 | J26: =+H26-I26 -> -2548.7931 | K26: =+G26-I26 -> -1648.7931
A27: =+'DETAIL CA MOIS'!B30 -> DACIA DUSTER WILA | B27: =+'DETAIL CA MOIS'!C30 -> M199903 | C27: =+'DETAIL CA MOIS'!D30 -> 9960 | D27: =+'DETAIL CA MOIS'!E30 -> 0 | E27: =+'DETAIL CA MOIS'!F30 -> 0 | F27: =+C27*0.15+40 -> 1534 | G27: =C27-F27 -> 8426 | H27: =+D27-F27 -> -1534 | I27: =70000/29 -> 2413.7931 | J27: =+H27-I27 -> -3947.7931 | K27: =+G27-I27 -> 6012.2069
A28: =+'DETAIL CA MOIS'!B31 -> DACIA DUSTER HARBIL | B28: =+'DETAIL CA MOIS'!C31 -> J 185418 | C28: =+'DETAIL CA MOIS'!D31 -> 9943.2 | D28: =+'DETAIL CA MOIS'!E31 -> 0 | E28: =+'DETAIL CA MOIS'!F31 -> 9943.2 | F28: =+C28*0.15+4850+70+60+40 -> 6511.48 | G28: =C28-F28 -> 3431.72 | H28: =+D28-F28 -> -6511.48 | I28: =70000/29 -> 2413.7931 | J28: =+H28-I28 -> -8925.2731 | K28: =+G28-I28 -> 1017.9269
A29: =+'DETAIL CA MOIS'!B32 -> DACIA LOGAN | B29: =+'DETAIL CA MOIS'!C32 -> 91092-A-26 | C29: =+'DETAIL CA MOIS'!D32 -> 6000 | D29: =+'DETAIL CA MOIS'!E32 -> 6000 | E29: =+'DETAIL CA MOIS'!F32 -> 0 | F29: =825+130+40 -> 995 | G29: =C29-F29 -> 5005 | H29: =+D29-F29 -> 5005 | I29: =70000/29 -> 2413.7931 | J29: =+H29-I29 -> 2591.2069 | K29: =+G29-I29 -> 2591.2069
A30: =+'DETAIL CA MOIS'!B33 -> PGT BOXER | B30: =+'DETAIL CA MOIS'!C33 -> M234914 | C30: =+'DETAIL CA MOIS'!D33 -> 6633 | D30: =+'DETAIL CA MOIS'!E33 -> 0 | E30: =+'DETAIL CA MOIS'!F33 -> 6633 | F30: =+C30*0.15+1140+200 -> 2334.95 | G30: =C30-F30 -> 4298.05 | H30: =+D30-F30 -> -2334.95 | I30: =70000/29 -> 2413.7931 | J30: =+H30-I30 -> -4748.7431 | K30: =+G30-I30 -> 1884.2569
A31: =+'DETAIL CA MOIS'!B34 -> PORSCHE 911 | B31: =+'DETAIL CA MOIS'!C34 -> ESPAGNE | C31: =+'DETAIL CA MOIS'!D34 -> 1000 | D31: =+'DETAIL CA MOIS'!E34 -> 1000 | E31: =+'DETAIL CA MOIS'!F34 -> 0 | G31: =C31-F31 -> 1000 | H31: =+D31-F31 -> 1000 | I31: =70000/29 -> 2413.7931 | J31: =+H31-I31 -> -1413.7931 | K31: =+G31-I31 -> -1413.7931
A32: =+'DETAIL CA MOIS'!B35 -> DACIA DUSTER - WILA | B32: =+'DETAIL CA MOIS'!C35 -> M218563 | C32: =+'DETAIL CA MOIS'!D35 -> 7200 | D32: =+'DETAIL CA MOIS'!E35 -> 0 | E32: =+'DETAIL CA MOIS'!F35 -> 7200 | F32: =+C32*0.15+1300+300+520+600+1150 -> 4950 | G32: =C32-F32 -> 2250 | H32: =+D32-F32 -> -4950 | I32: =70000/29 -> 2413.7931 | J32: =+H32-I32 -> -7363.7931 | K32: =+G32-I32 -> -163.7931
A33: =+'DETAIL CA MOIS'!B36 -> JEEP GD CHEROKEE | B33: =+'DETAIL CA MOIS'!C36 -> 41724 - T - 1 | C33: =+'DETAIL CA MOIS'!D36 -> 1968 | D33: =+'DETAIL CA MOIS'!E36 -> 0 | E33: =+'DETAIL CA MOIS'!F36 -> 1968 | G33: =C33-F33 -> 1968 | H33: =+D33-F33 -> 0 | I33: =70000/29 -> 2413.7931 | J33: =+H33-I33 -> -2413.7931 | K33: =+G33-I33 -> -445.7931
A34: =+'DETAIL CA MOIS'!B37 -> PEUGEOT PARTNER | B34: =+'DETAIL CA MOIS'!C37 -> M174633 | C34: =+'DETAIL CA MOIS'!D37 -> 4325 | D34: =+'DETAIL CA MOIS'!E37 -> 0 | E34: =+'DETAIL CA MOIS'!F37 -> 4325 | F34: =+C34*0.15+200+700 -> 1548.75 | G34: =C34-F34 -> 2776.25 | H34: =+D34-F34 -> -1548.75 | I34: =70000/29 -> 2413.7931 | J34: =+H34-I34 -> -3962.5431 | K34: =+G34-I34 -> 362.4569
A35: =+'DETAIL CA MOIS'!B38 -> DACIA LOGAN HARBIL | B35: =+'DETAIL CA MOIS'!C38 -> J204318 | C35: =+'DETAIL CA MOIS'!D38 -> 9962 | D35: =+'DETAIL CA MOIS'!E38 -> 0 | E35: =+'DETAIL CA MOIS'!F38 -> 9962 | F35: =+C35*0.15+300+600+280+75+280+165+100 -> 3294.3 | G35: =C35-F35 -> 6667.7 | H35: =+D35-F35 -> -3294.3 | I35: =70000/29 -> 2413.7931 | J35: =+H35-I35 -> -5708.0931 | K35: =+G35-I35 -> 4253.9069
A36: =+'DETAIL CA MOIS'!B39 -> FORD TRANSIT HARBIL | B36: =+'DETAIL CA MOIS'!C39 -> J207789 | C36: =+'DETAIL CA MOIS'!D39 -> 8380 | D36: =+'DETAIL CA MOIS'!E39 -> 0 | E36: =+'DETAIL CA MOIS'!F39 -> 8380 | F36: =+C36*0.15+1250 -> 2507 | G36: =C36-F36 -> 5873 | H36: =+D36-F36 -> -2507 | I36: =70000/29 -> 2413.7931 | J36: =+H36-I36 -> -4920.7931 | K36: =+G36-I36 -> 3459.2069
A37: =+'DETAIL CA MOIS'!B40 -> FIAT DOBLO HARBIL | B37: =+'DETAIL CA MOIS'!C40 -> J0248319 | C37: =+'DETAIL CA MOIS'!D40 -> 8380 | D37: =+'DETAIL CA MOIS'!E40 -> 0 | E37: =+'DETAIL CA MOIS'!F40 -> 8380 | F37: =+C37*0.15+1250 -> 2507 | G37: =C37-F37 -> 5873 | H37: =+D37-F37 -> -2507 | I37: =70000/29 -> 2413.7931 | J37: =+H37-I37 -> -4920.7931 | K37: =+G37-I37 -> 3459.2069
A38: =+'DETAIL CA MOIS'!B41 -> RENAULT MASTER HARB | B38: =+'DETAIL CA MOIS'!C41 -> J0257528 | C38: =+'DETAIL CA MOIS'!D41 -> 8380 | D38: =+'DETAIL CA MOIS'!E41 -> 0 | E38: =+'DETAIL CA MOIS'!F41 -> 8380 | F38: =+C38*0.15+1250 -> 2507 | G38: =C38-F38 -> 5873 | H38: =+D38-F38 -> -2507 | I38: =70000/29 -> 2413.7931 | J38: =+H38-I38 -> -4920.7931 | K38: =+G38-I38 -> 3459.2069
A39: =+'DETAIL CA MOIS'!B42 -> CLIO | B39: =+'DETAIL CA MOIS'!C42 -> 55449-D-26 | C39: =+'DETAIL CA MOIS'!D42 -> 0 | D39: =+'DETAIL CA MOIS'!E42 -> 0 | E39: =+'DETAIL CA MOIS'!F42 -> 0 | H39: =+D39-F39 -> 0 | I39: =70000/29 -> 2413.7931 | J39: =+H39-I39 -> -2413.7931 | K39: =+G39-I39 -> -2413.7931
A40: =+'DETAIL CA MOIS'!B43 -> VW PASSAT | B40: =+'DETAIL CA MOIS'!C43 -> M166303 | C40: =+'DETAIL CA MOIS'!D43 -> 1896 | D40: =+'DETAIL CA MOIS'!E43 -> 0 | E40: =+'DETAIL CA MOIS'!F43 -> 1896 | F40: =+C40*0.15 -> 284.4 | H40: =+D40-F40 -> -284.4 | I40: =70000/29 -> 2413.7931 | J40: =+H40-I40 -> -2698.1931 | K40: =+G40-I40 -> -2413.7931
A41: =+'DETAIL CA MOIS'!B44 -> RENAULT MASTER HARB | B41: =+'DETAIL CA MOIS'!C44 -> J0248320 | C41: =+'DETAIL CA MOIS'!D44 -> 8380 | D41: =+'DETAIL CA MOIS'!E44 -> 0 | E41: =+'DETAIL CA MOIS'!F44 -> 8380 | F41: =+C41*0.15+1250 -> 2507 | H41: =+D41-F41 -> -2507 | I41: =70000/29 -> 2413.7931 | J41: =+H41-I41 -> -4920.7931 | K41: =+G41-I41 -> -2413.7931
A42: =+'DETAIL CA MOIS'!B45 -> MITSUBISHI PAJERO SPORT HARB | B42: =+'DETAIL CA MOIS'!C45 -> J219569 | C42: =+'DETAIL CA MOIS'!D45 -> 8380 | D42: =+'DETAIL CA MOIS'!E45 -> 0 | E42: =+'DETAIL CA MOIS'!F45 -> 8380 | F42: =+C42*0.15+1250 -> 2507 | H42: =+D42-F42 -> -2507 | I42: =70000/29 -> 2413.7931 | J42: =+H42-I42 -> -4920.7931 | K42: =+G42-I42 -> -2413.7931
A43: =+'DETAIL CA MOIS'!B46 -> MERCEDES | B43: =+'DETAIL CA MOIS'!C46 -> 76786-B-26 | C43: =+'DETAIL CA MOIS'!D46 -> 0 | D43: =+'DETAIL CA MOIS'!E46 -> 0 | E43: =+'DETAIL CA MOIS'!F46 -> 0 | F43: =+C43*0.15+200+750 -> 950 | H43: =+D43-F43 -> -950 | I43: =70000/29 -> 2413.7931 | J43: =+H43-I43 -> -3363.7931 | K43: =+G43-I43 -> -2413.7931
A44: =+'DETAIL CA MOIS'!B47 -> RENAULT MASTER HARB | B44: =+'DETAIL CA MOIS'!C47 -> J0248320 | C44: =+'DETAIL CA MOIS'!D47 -> 3747 | D44: =+'DETAIL CA MOIS'!E47 -> 0 | E44: =+'DETAIL CA MOIS'!F47 -> 3747 | F44: =+C44*0.15 -> 562.05 | G44: =C44-F44 -> 3184.95 | H44: =+D44-F44 -> -562.05 | I44: =70000/29 -> 2413.7931 | J44: =+H44-I44 -> -2975.8431 | K44: =+G44-I44 -> 771.1569
A45: =+'DETAIL CA MOIS'!B48 -> MITSUBISHI PAJERO SPORT HARB | B45: =+'DETAIL CA MOIS'!C48 -> J219569 | C45: =+'DETAIL CA MOIS'!D48 -> 19290 | D45: =+'DETAIL CA MOIS'!E48 -> 0 | E45: =+'DETAIL CA MOIS'!F48 -> 19290 | F45: =+C45*0.15+500+50 -> 3443.5 | I45: =50000/32 -> 1562.5 | J45: =+H45-I45 -> -1562.5 | K45: =+G45-I45 -> -1562.5
A46: =+'DETAIL CA MOIS'!B49 -> PEUGEOT 208 | B46: =+'DETAIL CA MOIS'!C49 -> 80130-B-26 | C46: =+'DETAIL CA MOIS'!D49 -> 0 | D46: =+'DETAIL CA MOIS'!E49 -> 0 | E46: =+'DETAIL CA MOIS'!F59 -> 0 | G46: =C46-F46 -> 0 | H46: =+D46-F46 -> 0 | I46: =50000/32 -> 1562.5 | J46: =+H46-I46 -> -1562.5 | K46: =+G46-I46 -> -1562.5
...

Sheet REPART CA
D2: NBRE | E2: MOYENNE | H2: NARSA | I2: =+'DETAIL CA MOIS'!D16+'DETAIL CA MOIS'!D24 -> 5604
A3: ADMINISTRATION | B3: =+'DETAIL CA MOIS'!D15+'DETAIL CA MOIS'!D16+'DETAIL CA MOIS'!D17+'DETAIL CA MOIS'!D18+'DETAIL CA MOIS'!D19+'DETAIL CA MOIS'!D20+'DETAIL CA MOIS'!D22+'DETAIL CA MOIS'!D23+'DETAIL CA MOIS'!D24+'DETAIL CA MOIS'!D25+'DETAIL CA MOIS'!D28+'DETAIL CA MOIS'!D29+'DETAIL CA MOIS'!D30+'DETAIL CA MOIS'!D31+'DETAIL CA MOIS'!D33+'DETAIL CA MOIS'!D35 -> 82290.2 | C3: =+B3/B5 -> 0.87551894 | D3: 16 | E3: =+B3/D3 -> 5143.1375 | H3: PREFECTURE MKH | I3: =+'DETAIL CA MOIS'!D15+'DETAIL CA MOIS'!D19+'DETAIL CA MOIS'!D20+'DETAIL CA MOIS'!D23+'DETAIL CA MOIS'!D29+'DETAIL CA MOIS'!D33+'DETAIL CA MOIS'!D35 -> 43681 | J3: =+I3/B3 -> 0.53081655 | K3: =+'DETAIL CA MOIS'!D38+'DETAIL CA MOIS'!D39 -> 18342
A4: PARTICULIERS | B4: =+'DETAIL CA MOIS'!D13+'DETAIL CA MOIS'!D14+'DETAIL CA MOIS'!D21+'DETAIL CA MOIS'!D26+'DETAIL CA MOIS'!D27+'DETAIL CA MOIS'!D32 -> 11700 | C4: =+B4/B5 -> 0.12448106 | D4: 7 | E4: =+B4/D4 -> 1671.4286 | H4: PROTECTION CIVILE | J4: =+I4/B3 -> 0
B5: =SUM(B3:B4) -> 93990.2 | C5: =SUM(C3:C4) -> 1 | D5: =SUM(D3:D4) -> 23 | E5: =+B5/D5 -> 4086.5304 | H5: CR HARBIL | I5: =+'DETAIL CA MOIS'!D17+'DETAIL CA MOIS'!D18+'DETAIL CA MOIS'!D25+'DETAIL CA MOIS'!D28+'DETAIL CA MOIS'!D30+'DETAIL CA MOIS'!D31 -> 31085.2 | J5: =+I5/B3 -> 0.37775094
H6: CU MARRAKECH | J6: =+I6/B3 -> 0
H7: AMEE | J7: =+I7/B3 -> 0
I8: =SUM(I2:I7) -> 80370.2 | J8: =SUM(J3:J7) -> 0.90856748
